Workbook
Name Pct_Cesiones: #REF!
Name SA_abs: #REF!
Name SA_comerc: #REF!
Name SA_conting: #REF!
Name SA_GG_BI: #REF!
Name SA_honorarios: #REF!
Name SA_licencias: #REF!
Name SA_m2_media: #REF!
Name SA_precio_m2: #REF!
Name SA_unidades: #REF!
Name Sup_Parcela_Bruta: #REF!
Name Sup_Parcela_Neta: #REF!

Sheet 00_ESTRATEGIA
A1: SELECCIONES ESTRATÉGICAS | D1: INDICADORES DE RENTABILIDAD
A2: Variable | B2: Selección | D2: Métrica | E2: Venta | F2: Alquiler
A3: Tipología | B3: Unifamiliar seg. | D3: TIR | E3: ='30_CASHFLOW'!B45 -> 0.1367759 | F3: ='30_CASHFLOW'!C45 -> 0.0086677881
A4: Escenario | B4: Base | D4: VAN | E4: ='30_CASHFLOW'!B46 -> 468930.73 | F4: ='30_CASHFLOW'!C46 -> -2949614.9
A5: Horizonte (alquiler) | B5: 15 | D5: Tasa descuento (VAN) | E5: 0.08 | F5: 0.06
A6: Año inicial | B6: 2028
A7: Parcela bruta (m2) | B7: 9290
A8: Sensibilidad financiera | B8: Base
A11: INDICADORES CON FINANCIACIÓN (Capa Financiera)
A12: TIR (anualizada) | B12: ='30_CASHFLOW'!B49 -> 0.17348834
A13: VAN @ Ke | B13: ='30_CASHFLOW'!B50 -> 157181.39
A14: Capital propio máximo | B14: ='30_CASHFLOW'!B51 -> 1570326
A15: Coste suelo | B15: ='10_CAPEX-INGRESOS-PAGOS'!$B$16 -> 1183546
A16: Coste extra | B16: =B14-B15 -> 386780.02
A17: Equity multiple (MOIC) | B17: ='30_CASHFLOW'!B52 -> 1.3803175

Sheet 01_MODELO
A2: CONFIGURACIÓN TÉCNICA
A3: Parámetro | B3: Unifamiliar seg. | C3: Unifamiliar conj. | D3: Plurifamiliar U2C | E3: Plurifamiliar U4C | F3: Unidades | H3: Parámetro | I3: ='00_ESTRATEGIA'!B3 -> Unifamiliar seg.
A4: Parcela | H4: =A4 -> Parcela
A5: Superficie parcela bruta | B5: ='00_ESTRATEGIA'!$B$7 -> 9290 | C5: ='00_ESTRATEGIA'!$B$7 -> 9290 | D5: ='00_ESTRATEGIA'!$B$7 -> 9290 | E5: ='00_ESTRATEGIA'!$B$7 -> 9290 | F5: m² | H5: =A5 -> Superficie parcela bruta | I5: {=_xlfn.SWITCH($I$3,$B$3,B5,$C$3,C5,$D$3,D5,$E$3,E5)} -> 9290
A6: % cesiones / afecciones | B6: 0 | C6: 0 | D6: 0 | E6: 0 | F6: % | H6: =A6 -> % cesiones / afecciones | I6: {=_xlfn.SWITCH($I$3,$B$3,B6,$C$3,C6,$D$3,D6,$E$3,E6)} -> 0
A7: Superficie parcela neta | B7: =B5*(1-B6) -> 9290 | C7: =C5*(1-C6) -> 9290 | D7: =D5*(1-D6) -> 9290 | E7: =E5*(1-E6) -> 9290 | F7: m² | H7: =A7 -> Superficie parcela neta | I7: {=_xlfn.SWITCH($I$3,$B$3,B7,$C$3,C7,$D$3,D7,$E$3,E7)} -> 9290
A8: Parámetros urbanísticos | H8: =A8 -> Parámetros urbanísticos
A9: Ordenanza aplicable | B9: U2 | C9: U2 | D9: U2C | E9: U4C | F9: — | H9: =A9 -> Ordenanza aplicable | I9: {=_xlfn.SWITCH($I$3,$B$3,B9,$C$3,C9,$D$3,D9,$E$3,E9)} -> U2
A10: Superficie ámbito | B10: =$B$7 -> 9290 | C10: =$B$7 -> 9290 | D10: =$B$7 -> 9290 | E10: =$B$7 -> 9290 | F10: m² | H10: =A10 -> Superficie ámbito | I10: {=_xlfn.SWITCH($I$3,$B$3,B10,$C$3,C10,$D$3,D10,$E$3,E10)} -> 9290
A11: Edificabilidad | B11: 0.45 | C11: 0.45 | D11: 0.45 | E11: 0.65 | F11: m²/m² | H11: =A11 -> Edificabilidad | I11: {=_xlfn.SWITCH($I$3,$B$3,B11,$C$3,C11,$D$3,D11,$E$3,E11)} -> 0.45
A12: Ocupación | B12: 0.25 | C12: 0.25 | D12: 0.2 | E12: 0.2 | F12: % | H12: =A12 -> Ocupación | I12: {=_xlfn.SWITCH($I$3,$B$3,B12,$C$3,C12,$D$3,D12,$E$3,E12)} -> 0.25
A13: Número máximo de plantas | B13: 2 | C13: 2 | D13: 3 | E13: 4 | F13: plantas | H13: =A13 -> Número máximo de plantas | I13: {=_xlfn.SWITCH($I$3,$B$3,B13,$C$3,C13,$D$3,D13,$E$3,E13)} -> 2
A14: Altura máxima | B14: 7 | C14: 7 | D14: 10 | E14: 13 | F14: m | H14: =A14 -> Altura máxima | I14: {=_xlfn.SWITCH($I$3,$B$3,B14,$C$3,C14,$D$3,D14,$E$3,E14)} -> 7
A15: Capacidad edificatoria | H15: =A15 -> Capacidad edificatoria | I15: =_xlfn.SWITCH($I$3,$B$3,B15,$C$3,C15,$D$3,D15,$E$3,E15) -> 0
A16: Techo máximo edificable | B16: =B10*B11 -> 4180.5 | C16: =C10*C11 -> 4180.5 | D16: =D10*D11 -> 4180.5 | E16: =E10*E11 -> 6038.5 | F16: m² | H16: =A16 -> Techo máximo edificable | I16: {=_xlfn.SWITCH($I$3,$B$3,B16,$C$3,C16,$D$3,D16,$E$3,E16)} -> 4180.5
A17: Huella máxima en planta | B17: =B10*B12 -> 2322.5 | C17: =C10*C12 -> 2322.5 | D17: =D10*D12 -> 1858 | E17: =E10*E12 -> 1858 | F17: m² | H17: =A17 -> Huella máxima en planta | I17: {=_xlfn.SWITCH($I$3,$B$3,B17,$C$3,C17,$D$3,D17,$E$3,E17)} -> 2322.5
A18: Eficiencia edificatoria | B18: 1 | C18: 1 | D18: 0.85 | E18: 0.85 | F18: % | H18: =A18 -> Eficiencia edificatoria | I18: {=_xlfn.SWITCH($I$3,$B$3,B18,$C$3,C18,$D$3,D18,$E$3,E18)} -> 1
A19: Definición del producto | H19: =A19 -> Definición del producto
A20: Parcela mínima | B20: 700 | C20: No aplica | D20: No aplica | E20: No aplica | F20: m² | H20: =A20 -> Parcela mínima | I20: {=_xlfn.SWITCH($I$3,$B$3,B20,$C$3,C20,$D$3,D20,$E$3,E20)} -> 700
A21: Parcela media | B21: =B10/B29 -> 714.61538 | C21: =C10/C29 -> 546.47059 | D21: No aplica | E21: No aplica | F21: m² | H21: =A21 -> Parcela media | I21: {=_xlfn.SWITCH($I$3,$B$3,B21,$C$3,C21,$D$3,D21,$E$3,E21)} -> 714.61538
A22: Huella por vivienda | B22: =B21*B12 -> 178.65385 | C22: =C21*C12 -> 136.61765 | D22: No aplica | E22: No aplica | F22: m² | H22: =A22 -> Huella por vivienda | I22: {=_xlfn.SWITCH($I$3,$B$3,B22,$C$3,C22,$D$3,D22,$E$3,E22)} -> 178.65385
A23: Parcela libre | B23: =B21-B22 -> 535.96154 | C23: =C21-C22 -> 409.85294 | D23: No aplica | E23: No aplica | F23: m² | H23: =A23 -> Parcela libre | I23: {=_xlfn.SWITCH($I$3,$B$3,B23,$C$3,C23,$D$3,D23,$E$3,E23)} -> 535.96154
A24: Tamaño mínimo vivienda | B24: 240 | C24: 240 | D24: 90 | E24: 90 | F24: m² | H24: =A24 -> Tamaño mínimo vivienda | I24: {=_xlfn.SWITCH($I$3,$B$3,B24,$C$3,C24,$D$3,D24,$E$3,E24)} -> 240
A25: Tamaño máximo vivienda | B25: =B16/B29 -> 321.57692 | C25: =C16/C29 -> 245.91176 | D25: =D24 -> 90 | E25: =E24 -> 90 | F25: m² | H25: =A25 -> Tamaño máximo vivienda | I25: {=_xlfn.SWITCH($I$3,$B$3,B25,$C$3,C25,$D$3,D25,$E$3,E25)} -> 321.57692
A26: Tamaño elegido vivienda | B26: =B24 -> 240 | C26: =C24 -> 240 | D26: =D24 -> 90 | E26: =E24 -> 90 | F26: m² | H26: =A26 -> Tamaño elegido vivienda | I26: {=_xlfn.SWITCH($I$3,$B$3,B26,$C$3,C26,$D$3,D26,$E$3,E26)} -> 240
A27: Resultado físico del proyecto | H27: =A27 -> Resultado físico del proyecto
A28: Superficie construida media | B28: =B26 -> 240 | C28: =C26 -> 240 | D28: =D26 -> 90 | E28: =E26 -> 90 | F28: m² | H28: =A28 -> Superficie construida media | I28: {=_xlfn.SWITCH($I$3,$B$3,B28,$C$3,C28,$D$3,D28,$E$3,E28)} -> 240
A29: Número estimado de unidades | B29: =INT(IF(B20<>"No aplica",INT(B10/B20),B16*B18/B24)) -> 13 | C29: =INT(IF(C20<>"No aplica",INT(C10/C20),C16*C18/C24)) -> 17 | D29: =INT(IF(D20<>"No aplica",INT(D10/D20),D16*D18/D24)) -> 39 | E29: =INT(IF(E20<>"No aplica",INT(E10/E20),E16*E18/E24)) -> 57 | F29: unidades | H29: =A29 -> Número estimado de unidades | I29: {=_xlfn.SWITCH($I$3,$B$3,B29,$C$3,C29,$D$3,D29,$E$3,E29)} -> 13
A30: Huella en planta | B30: =B28/B13 -> 120 | C30: =C28/C13 -> 120 | D30: =D29*D28/D13 -> 1170 | E30: =E29*E28/E13 -> 1282.5 | F30: m² | H30: =A30 -> Huella en planta | I30: {=_xlfn.SWITCH($I$3,$B$3,B30,$C$3,C30,$D$3,D30,$E$3,E30)} -> 120
A31: Variables temporales | H31: =A31 -> Variables temporales
A32: Año inicio proyecto | B32: 0 | C32: 0 | D32: 0 | E32: 0 | F32: año | H32: =A32 -> Año inicio proyecto | I32: {=_xlfn.SWITCH($I$3,$B$3,B32,$C$3,C32,$D$3,D32,$E$3,E32)} -> 0
A33: Fase de diseño | B33: {=5*(1+_xlfn.SWITCH('02_ESCENARIOS'!$G$2,'02_ESCENARIOS'!$B$2,'02_ESCENARIOS'!$B$17,'02_ESCENARIOS'!$C$2,'02_ESCENARIOS'!$C$17,'02_ESCENARIOS'!$D$2,'02_ESCENARIOS'!$D$17))} -> 5 | C33: {=5*(1+_xlfn.SWITCH('02_ESCENARIOS'!$G$2,'02_ESCENARIOS'!$B$2,'02_ESCENARIOS'!$B$17,'02_ESCENARIOS'!$C$2,'02_ESCENARIOS'!$C$17,'02_ESCENARIOS'!$D$2,'02_ESCENARIOS'!$D$17))} -> 5 | D33: {=5*(1+_xlfn.SWITCH('02_ESCENARIOS'!$G$2,'02_ESCENARIOS'!$B$2,'02_ESCENARIOS'!$B$17,'02_ESCENARIOS'!$C$2,'02_ESCENARIOS'!$C$17,'02_ESCENARIOS'!$D$2,'02_ESCENARIOS'!$D$17))} -> 5 | E33: {=5*(1+_xlfn.SWITCH('02_ESCENARIOS'!$G$2,'02_ESCENARIOS'!$B$2,'02_ESCENARIOS'!$B$17,'02_ESCENARIOS'!$C$2,'02_ESCENARIOS'!$C$17,'02_ESCENARIOS'!$D$2,'02_ESCENARIOS'!$D$17))} -> 5 | F33: meses | H33: =A33 -> Fase de diseño | I33: {=_xlfn.SWITCH($I$3,$B$3,B33,$C$3,C33,$D$3,D33,$E$3,E33)} -> 5
A34: Fase de licitaciones y permisos | B34: {=6*(1+_xlfn.SWITCH('02_ESCENARIOS'!$G$2,'02_ESCENARIOS'!$B$2,'02_ESCENARIOS'!$B$17,'02_ESCENARIOS'!$C$2,'02_ESCENARIOS'!$C$17,'02_ESCENARIOS'!$D$2,'02_ESCENARIOS'!$D$17))} -> 6 | C34: {=6*(1+_xlfn.SWITCH('02_ESCENARIOS'!$G$2,'02_ESCENARIOS'!$B$2,'02_ESCENARIOS'!$B$17,'02_ESCENARIOS'!$C$2,'02_ESCENARIOS'!$C$17,'02_ESCENARIOS'!$D$2,'02_ESCENARIOS'!$D$17))} -> 6 | D34: {=6*(1+_xlfn.SWITCH('02_ESCENARIOS'!$G$2,'02_ESCENARIOS'!$B$2,'02_ESCENARIOS'!$B$17,'02_ESCENARIOS'!$C$2,'02_ESCENARIOS'!$C$17,'02_ESCENARIOS'!$D$2,'02_ESCENARIOS'!$D$17))} -> 6 | E34: {=6*(1+_xlfn.SWITCH('02_ESCENARIOS'!$G$2,'02_ESCENARIOS'!$B$2,'02_ESCENARIOS'!$B$17,'02_ESCENARIOS'!$C$2,'02_ESCENARIOS'!$C$17,'02_ESCENARIOS'!$D$2,'02_ESCENARIOS'!$D$17))} -> 6 | F34: meses | H34: =A34 -> Fase de licitaciones y permisos | I34: {=_xlfn.SWITCH($I$3,$B$3,B34,$C$3,C34,$D$3,D34,$E$3,E34)} -> 6
A35: Inicio obra | B35: =B32+(B33+B34) -> 11 | C35: =C32+(C33+C34) -> 11 | D35: =D32+(D33+D34) -> 11 | E35: =E32+(E33+E34) -> 11 | F35: mes | H35: =A35 -> Inicio obra | I35: {=_xlfn.SWITCH($I$3,$B$3,B35,$C$3,C35,$D$3,D35,$E$3,E35)} -> 11
A36: Duración obra (meses) | B36: {=24*(1+_xlfn.SWITCH('02_ESCENARIOS'!$G$2,'02_ESCENARIOS'!B2,'02_ESCENARIOS'!B17,'02_ESCENARIOS'!C2,'02_ESCENARIOS'!C17,'02_ESCENARIOS'!D2,'02_ESCENARIOS'!D17))} -> 24 | C36: {=24*(1+_xlfn.SWITCH('02_ESCENARIOS'!$G$2,'02_ESCENARIOS'!B2,'02_ESCENARIOS'!B17,'02_ESCENARIOS'!C2,'02_ESCENARIOS'!C17,'02_ESCENARIOS'!D2,'02_ESCENARIOS'!D17))} -> 24 | D36: {=25*(1+_xlfn.SWITCH('02_ESCENARIOS'!$G$2,'02_ESCENARIOS'!B2,'02_ESCENARIOS'!B17,'02_ESCENARIOS'!C2,'02_ESCENARIOS'!C17,'02_ESCENARIOS'!D2,'02_ESCENARIOS'!D17))} -> 25 | E36: {=27*(1+_xlfn.SWITCH('02_ESCENARIOS'!$G$2,'02_ESCENARIOS'!B2,'02_ESCENARIOS'!B17,'02_ESCENARIOS'!C2,'02_ESCENARIOS'!C17,'02_ESCENARIOS'!D2,'02_ESCENARIOS'!D17))} -> 27 | F36: meses | H36: =A36 -> Duración obra (meses) | I36: {=_xlfn.SWITCH($I$3,$B$3,B36,$C$3,C36,$D$3,D36,$E$3,E36)} -> 24
A37: Fin obra | B37: =B35+B36 -> 35 | C37: =C35+C36 -> 35 | D37: =D35+D36 -> 36 | E37: =E35+E36 -> 38 | F37: mes | H37: =A37 -> Fin obra | I37: {=_xlfn.SWITCH($I$3,$B$3,B37,$C$3,C37,$D$3,D37,$E$3,E37)} -> 35
A38: Variables de coste | H38: =A38 -> Variables de coste | I38: =_xlfn.SWITCH($I$3,$B$3,B38,$C$3,C38,$D$3,D38,$E$3,E38) -> 0
A39: Coste ejecución material | B39: 1323 | C39: =B39 -> 1323 | D39: =C39 -> 1323 | E39: =D39 -> 1323 | F39: €/m² | H39: =A39 -> Coste ejecución material | I39: {=_xlfn.SWITCH($I$3,$B$3,B39,$C$3,C39,$D$3,D39,$E$3,E39)} -> 1323
A40: Factor tipología | B40: 1.12 | C40: 1.08 | D40: 0.92 | E40: 0.97 | F40: — | H40: =A40 -> Factor tipología | I40: {=_xlfn.SWITCH($I$3,$B$3,B40,$C$3,C40,$D$3,D40,$E$3,E40)} -> 1.12
A41: Gastos generales + BI | B41: {=20%+_xlfn.SWITCH('00_ESTRATEGIA'!$B$4,'02_ESCENARIOS'!$B$2,'02_ESCENARIOS'!$B4,'02_ESCENARIOS'!$C$2,'02_ESCENARIOS'!$C4,'02_ESCENARIOS'!$D$2,'02_ESCENARIOS'!$D4)} -> 0.2 | C41: =B41 -> 0.2 | D41: =C41 -> 0.2 | E41: =D41 -> 0.2 | F41: % | H41: =A41 -> Gastos generales + BI | I41: {=_xlfn.SWITCH($I$3,$B$3,B41,$C$3,C41,$D$3,D41,$E$3,E41)} -> 0.2
...

Sheet 02_ESCENARIOS
A1: ESCENARIOS ECONÓMICO-FINANCIEROS
A2: Variable | B2: Conservador | C2: Base | D2: Optimista | F2: Selección | G2: ='00_ESTRATEGIA'!B4 -> Base
A3: Variables de construcción | F3: =A3 -> Variables de construcción
A4: GG + BI | B4: 0.01 | C4: 0 | D4: -0.01 | F4: =A4 -> GG + BI | G4: {=_xlfn.SWITCH($G$2,$B$2,B4,$C$2,C4,$D$2,D4)} -> 0
A5: Contingencia | B5: 0.02 | C5: 0 | D5: -0.02 | F5: =A5 -> Contingencia | G5: {=_xlfn.SWITCH($G$2,$B$2,B5,$C$2,C5,$D$2,D5)} -> 0
A6: Licencias y tasas | B6: 0.005 | C6: 0 | D6: -0.005 | F6: =A6 -> Licencias y tasas | G6: {=_xlfn.SWITCH($G$2,$B$2,B6,$C$2,C6,$D$2,D6)} -> 0
A7: Honorarios | B7: 0.01 | C7: 0 | D7: -0.01 | F7: =A7 -> Honorarios | G7: {=_xlfn.SWITCH($G$2,$B$2,B7,$C$2,C7,$D$2,D7)} -> 0
A8: Variables de venta | F8: =A8 -> Variables de venta
A9: Delta comercialización (pp) | B9: 0.005 | C9: 0 | D9: -0.005 | F9: =A9 -> Delta comercialización (pp) | G9: {=_xlfn.SWITCH($G$2,$B$2,B9,$C$2,C9,$D$2,D9)} -> 0
A10: Ritmo de absorción (multiplicador) | B10: 0.8 | C10: 1 | D10: 1.2 | F10: =A10 -> Ritmo de absorción (multiplicador) | G10: {=_xlfn.SWITCH($G$2,$B$2,B10,$C$2,C10,$D$2,D10)} -> 1
A11: Variables de alquiler | F11: =A11 -> Variables de alquiler
A12: Ocupación estabilizada | B12: -0.03 | C12: 0 | D12: 0.03 | F12: =A12 -> Ocupación estabilizada | G12: {=_xlfn.SWITCH($G$2,$B$2,B12,$C$2,C12,$D$2,D12)} -> 0
A13: Gastos explotación OPEX | B13: 0.04 | C13: 0 | D13: -0.04 | F13: =A13 -> Gastos explotación OPEX | G13: {=_xlfn.SWITCH($G$2,$B$2,B13,$C$2,C13,$D$2,D13)} -> 0
A14: Crecimiento anual rentas | B14: -0.005 | C14: 0 | D14: 0.005 | F14: =A14 -> Crecimiento anual rentas | G14: {=_xlfn.SWITCH($G$2,$B$2,B14,$C$2,C14,$D$2,D14)} -> 0
A15: Yield / cap rate salida | B15: 0.005 | C15: 0 | D15: -0.005 | F15: =A15 -> Yield / cap rate salida | G15: {=_xlfn.SWITCH($G$2,$B$2,B15,$C$2,C15,$D$2,D15)} -> 0
A16: Variables de temporales | F16: =A16 -> Variables de temporales
A17: Factor temporal (obra, licitaciones,diseño) | B17: 0.2 | C17: 0 | D17: -0.1 | F17: =A17 -> Factor temporal (obra, licitaciones,diseño) | G17: {=_xlfn.SWITCH($G$2,$B$2,B17,$C$2,C17,$D$2,D17)} -> 0
A19: SENSIBILIDAD FINANCIERA (independiente del escenario)
A20: Variable | B20: Adverso | C20: Base | D20: Favorable | F20: Seleccion | G20: ='00_ESTRATEGIA'!B8 -> Base
A21: Delta coste de la deuda (Euribor) | B21: 0.015 | C21: 0 | D21: -0.015 | F21: =A21 -> Delta coste de la deuda (Euribor) | G21: {=_xlfn.SWITCH($G$20,$B$20,B21,$C$20,C21,$D$20,D21)} -> 0

Sheet 10_CAPEX-INGRESOS-PAGOS
A1: CAPEX
A2: Variable | B2: Unifamiliar seg. | C2: Unifamiliar conj. | D2: Plurifamiliar U2C | E2: Plurifamiliar U4C | G2: Selección | H2: ='00_ESTRATEGIA'!B3 -> Unifamiliar seg.
A3: Número de viviendas | B3: ='01_MODELO'!B29 -> 13 | C3: ='01_MODELO'!C29 -> 17 | D3: ='01_MODELO'!D29 -> 39 | E3: ='01_MODELO'!E29 -> 57 | G3: =A3 -> Número de viviendas | H3: {=_xlfn.SWITCH($H$2,$B$2,B3,$C$2,C3,$D$2,D3,$E$2,E3)} -> 13
A4: Superficie por vivienda (m²) | B4: ='01_MODELO'!B26 -> 240 | C4: ='01_MODELO'!C26 -> 240 | D4: ='01_MODELO'!D26 -> 90 | E4: ='01_MODELO'!E26 -> 90 | G4: =A4 -> Superficie por vivienda (m²) | H4: {=_xlfn.SWITCH($H$2,$B$2,B4,$C$2,C4,$D$2,D4,$E$2,E4)} -> 240
A5: Superficie total (m²) | B5: =B3*B4 -> 3120 | C5: =C3*C4 -> 4080 | D5: ='01_MODELO'!D16 -> 4180.5 | E5: ='01_MODELO'!E16 -> 6038.5 | G5: =A5 -> Superficie total (m²) | H5: {=_xlfn.SWITCH($H$2,$B$2,B5,$C$2,C5,$D$2,D5,$E$2,E5)} -> 3120
A6: Cem unitario (€/m²) | B6: ='01_MODELO'!B39*'01_MODELO'!B40 -> 1481.76 | C6: ='01_MODELO'!C39*'01_MODELO'!C40 -> 1428.84 | D6: ='01_MODELO'!D39*'01_MODELO'!D40 -> 1217.16 | E6: ='01_MODELO'!E39*'01_MODELO'!E40 -> 1283.31 | G6: =A6 -> Cem unitario (€/m²) | H6: {=_xlfn.SWITCH($H$2,$B$2,B6,$C$2,C6,$D$2,D6,$E$2,E6)} -> 1481.76
A7: PEM Total (€) | B7: =B6*B5 -> 4623091.2 | C7: =C6*C5 -> 5829667.2 | D7: =D6*D5 -> 5088337.4 | E7: =E6*E5 -> 7749267.4 | G7: =A7 -> PEM Total (€) | H7: {=_xlfn.SWITCH($H$2,$B$2,B7,$C$2,C7,$D$2,D7,$E$2,E7)} -> 4623091.2
A8: GG+BI (€) | B8: =B$7*'01_MODELO'!B41 -> 924618.24 | C8: =C$7*'01_MODELO'!C41 -> 1165933.4 | D8: =D$7*'01_MODELO'!D41 -> 1017667.5 | E8: =E$7*'01_MODELO'!E41 -> 1549853.5 | G8: =A8 -> GG+BI (€) | H8: {=_xlfn.SWITCH($H$2,$B$2,B8,$C$2,C8,$D$2,D8,$E$2,E8)} -> 924618.24
A9: Licencias (€) | B9: =B$7*'01_MODELO'!B43 -> 208039.1 | C9: =C$7*'01_MODELO'!C43 -> 262335.02 | D9: =D$7*'01_MODELO'!D43 -> 228975.18 | E9: =E$7*'01_MODELO'!E43 -> 348717.03 | G9: =A9 -> Licencias (€) | H9: {=_xlfn.SWITCH($H$2,$B$2,B9,$C$2,C9,$D$2,D9,$E$2,E9)} -> 208039.1
A10: Contingencia (€) | B10: =B$7*'01_MODELO'!B42 -> 346731.84 | C10: =C$7*'01_MODELO'!C42 -> 408076.7 | D10: =D$7*'01_MODELO'!D42 -> 305300.24 | E10: =E$7*'01_MODELO'!E42 -> 464956.05 | G10: =A10 -> Contingencia (€) | H10: {=_xlfn.SWITCH($H$2,$B$2,B10,$C$2,C10,$D$2,D10,$E$2,E10)} -> 346731.84
A11: Honorarios (€) | B11: =B$7*'01_MODELO'!B44 -> 369847.3 | C11: =C$7*'01_MODELO'!C44 -> 466373.38 | D11: =D$7*'01_MODELO'!D44 -> 457950.36 | E11: =E$7*'01_MODELO'!E44 -> 697434.07 | G11: =A11 -> Honorarios (€) | H11: {=_xlfn.SWITCH($H$2,$B$2,B11,$C$2,C11,$D$2,D11,$E$2,E11)} -> 369847.3
A12: Coste total construcción (€) | B12: =SUM(B7:B11) -> 6472327.7 | C12: =SUM(C7:C11) -> 8132385.7 | D12: =SUM(D7:D11) -> 7098230.6 | E12: =SUM(E7:E11) -> 10810228 | G12: =A12 -> Coste total construcción (€) | H12: {=_xlfn.SWITCH($H$2,$B$2,B12,$C$2,C12,$D$2,D12,$E$2,E12)} -> 6472327.7
A13: Coste total (€/m²) | B13: =B12/B5 -> 2074.464 | C13: =C12/C5 -> 1993.2318 | D13: =D12/D5 -> 1697.9382 | E13: =E12/E5 -> 1790.2175 | G13: =A13 -> Coste total (€/m²) | H13: {=_xlfn.SWITCH($H$2,$B$2,B13,$C$2,C13,$D$2,D13,$E$2,E13)} -> 2074.464
A14: Coste total por vivienda (€) | B14: =B12/B3 -> 497871.36 | C14: =C12/C3 -> 478375.63 | D14: =D12/D3 -> 182005.91 | E14: =E12/E3 -> 189653.12 | G14: =A14 -> Coste total por vivienda (€) | H14: {=_xlfn.SWITCH($H$2,$B$2,B14,$C$2,C14,$D$2,D14,$E$2,E14)} -> 497871.36
A15: Precio suelo (€/m²) | B15: 127.4 | C15: 127.4 | D15: 127.4 | E15: 127.4 | G15: =A15 -> Precio suelo (€/m²) | H15: {=_xlfn.SWITCH($H$2,$B$2,B15,$C$2,C15,$D$2,D15,$E$2,E15)} -> 127.4
A16: Coste parcela total (€) | B16: ='01_MODELO'!$B$5*'10_CAPEX-INGRESOS-PAGOS'!B15 -> 1183546 | C16: ='01_MODELO'!$B$5*'10_CAPEX-INGRESOS-PAGOS'!C15 -> 1183546 | D16: ='01_MODELO'!$B$5*'10_CAPEX-INGRESOS-PAGOS'!D15 -> 1183546 | E16: ='01_MODELO'!$B$5*'10_CAPEX-INGRESOS-PAGOS'!E15 -> 1183546 | G16: =A16 -> Coste parcela total (€) | H16: {=_xlfn.SWITCH($H$2,$B$2,B16,$C$2,C16,$D$2,D16,$E$2,E16)} -> 1183546
A17: Coste suelo por vivienda (€) | B17: =B16/B3 -> 91042 | C17: =C16/C3 -> 69620.353 | D17: =D16/D3 -> 30347.333 | E17: =E16/E3 -> 20763.965 | G17: =A17 -> Coste suelo por vivienda (€) | H17: {=_xlfn.SWITCH($H$2,$B$2,B17,$C$2,C17,$D$2,D17,$E$2,E17)} -> 91042
A18: Coste total + suelo (€) | B18: =B12+B16 -> 7655873.7 | C18: =C12+C16 -> 9315931.7 | D18: =D12+D16 -> 8281776.6 | E18: =E12+E16 -> 11993774 | G18: =A18 -> Coste total + suelo (€) | H18: {=_xlfn.SWITCH($H$2,$B$2,B18,$C$2,C18,$D$2,D18,$E$2,E18)} -> 7655873.7
A19: Coste total + suelo por vivienda (€) | B19: =B18/B3 -> 588913.36 | C19: =C18/C3 -> 547995.98 | D19: =D18/D3 -> 212353.25 | E19: =E18/E3 -> 210417.09 | G19: =A19 -> Coste total + suelo por vivienda (€) | H19: {=_xlfn.SWITCH($H$2,$B$2,B19,$C$2,C19,$D$2,D19,$E$2,E19)} -> 588913.36
A20: Coste total + suelo (€/m²) | B20: =B18/B5 -> 2453.8057 | C20: =C18/C5 -> 2283.3166 | D20: =D18/D5 -> 1981.0493 | E20: =E18/E5 -> 1986.2175 | G20: =A20 -> Coste total + suelo (€/m²) | H20: {=_xlfn.SWITCH($H$2,$B$2,B20,$C$2,C20,$D$2,D20,$E$2,E20)} -> 2453.8057
A22: INGRESOS
A23: Variable | B23: Unifamiliar seg. | C23: Unifamiliar conj. | D23: Plurifamiliar U2C | E23: Plurifamiliar U4C | G23: Selección | H23: ='00_ESTRATEGIA'!B3 -> Unifamiliar seg.
A24: Número viviendas (N) | B24: ='01_MODELO'!B29 -> 13 | C24: ='01_MODELO'!C29 -> 17 | D24: ='01_MODELO'!D29 -> 39 | E24: ='01_MODELO'!E29 -> 57 | G24: =A24 -> Número viviendas (N) | H24: {=_xlfn.SWITCH($H$23,$B$23,B24,$C$23,C24,$D$23,D24,$E$23,E24)} -> 13
A25: VENTA | G25: =A25 -> VENTA
A26: Superficie media (m2) | B26: ='01_MODELO'!B26 -> 240 | C26: ='01_MODELO'!C26 -> 240 | D26: ='01_MODELO'!D26 -> 90 | E26: ='01_MODELO'!E26 -> 90 | G26: =A26 -> Superficie media (m2) | H26: {=_xlfn.SWITCH($H$23,$B$23,B26,$C$23,C26,$D$23,D26,$E$23,E26)} -> 240
A27: Precio medio por unidad (€) | B27: 715000 | C27: 640000 | D27: 315000 | E27: 315000 | G27: =A27 -> Precio medio por unidad (€) | H27: {=_xlfn.SWITCH($H$23,$B$23,B27,$C$23,C27,$D$23,D27,$E$23,E27)} -> 715000
A28: Ingresos brutos totales (€) | B28: =B24*B27 -> 9295000 | C28: =C24*C27 -> 10880000 | D28: =D24*D27 -> 12285000 | E28: =E24*E27 -> 17955000 | G28: =A28 -> Ingresos brutos totales (€) | H28: {=_xlfn.SWITCH($H$23,$B$23,B28,$C$23,C28,$D$23,D28,$E$23,E28)} -> 9295000
A29: Comercialización (%) | B29: ='01_MODELO'!B63 -> 0.03 | C29: ='01_MODELO'!C63 -> 0.03 | D29: ='01_MODELO'!D63 -> 0.04 | E29: ='01_MODELO'!E63 -> 0.04 | G29: =A29 -> Comercialización (%) | H29: {=_xlfn.SWITCH($H$23,$B$23,B29,$C$23,C29,$D$23,D29,$E$23,E29)} -> 0.03
A30: Coste comercialización (€) | B30: =B28*B29 -> 278850 | C30: =C28*C29 -> 326400 | D30: =D28*D29 -> 491400 | E30: =E28*E29 -> 718200 | G30: =A30 -> Coste comercialización (€) | H30: {=_xlfn.SWITCH($H$23,$B$23,B30,$C$23,C30,$D$23,D30,$E$23,E30)} -> 278850
A31: Ingresos netos promotor (€) | B31: =B28-B30 -> 9016150 | C31: =C28-C30 -> 10553600 | D31: =D28-D30 -> 11793600 | E31: =E28-E30 -> 17236800 | G31: =A31 -> Ingresos netos promotor (€) | H31: {=_xlfn.SWITCH($H$23,$B$23,B31,$C$23,C31,$D$23,D31,$E$23,E31)} -> 9016150
A32: Ventas anuales | B32: =MIN(B24,12*'01_MODELO'!B64) -> 13 | C32: =MIN(C24,12*'01_MODELO'!C64) -> 15 | D32: =MIN(D24,12*'01_MODELO'!D64) -> 39 | E32: =MIN(E24,12*'01_MODELO'!E64) -> 48 | G32: =A32 -> Ventas anuales | H32: {=_xlfn.SWITCH($H$23,$B$23,B32,$C$23,C32,$D$23,D32,$E$23,E32)} -> 13
A33: ALQUILER | G33: =A33 -> ALQUILER
A34: Renta mensual por unidad (€) | B34: ='01_MODELO'!B72 -> 1815.3496 | C34: ='01_MODELO'!C72 -> 1628.7069 | D34: ='01_MODELO'!D72 -> 1039 | E34: ='01_MODELO'!E72 -> 1039 | G34: =A34 -> Renta mensual por unidad (€) | H34: {=_xlfn.SWITCH($H$23,$B$23,B34,$C$23,C34,$D$23,D34,$E$23,E34)} -> 1815.3496
A35: Ingreso bruto anual (€) | B35: =B24*B34*12 -> 283194.54 | C35: =C24*C34*12 -> 332256.21 | D35: =D24*D34*12 -> 486252 | E35: =E24*E34*12 -> 710676 | G35: =A35 -> Ingreso bruto anual (€) | H35: {=_xlfn.SWITCH($H$23,$B$23,B35,$C$23,C35,$D$23,D35,$E$23,E35)} -> 283194.54
A36: Ocupación estabilizada (%) | B36: ='01_MODELO'!B74 -> 0.93 | C36: ='01_MODELO'!C74 -> 0.93 | D36: ='01_MODELO'!D74 -> 0.93 | E36: ='01_MODELO'!E74 -> 0.93 | G36: =A36 -> Ocupación estabilizada (%) | H36: {=_xlfn.SWITCH($H$23,$B$23,B36,$C$23,C36,$D$23,D36,$E$23,E36)} -> 0.93
A37: Ingreso efectivo (€) | B37: =B35*B36 -> 263370.92 | C37: =C35*C36 -> 308998.27 | D37: =D35*D36 -> 452214.36 | E37: =E35*E36 -> 660928.68 | G37: =A37 -> Ingreso efectivo (€) | H37: {=_xlfn.SWITCH($H$23,$B$23,B37,$C$23,C37,$D$23,D37,$E$23,E37)} -> 263370.92
A38: Gastos explotación (% renta) | B38: ='01_MODELO'!B75 -> 0.28 | C38: ='01_MODELO'!C75 -> 0.28 | D38: ='01_MODELO'!D75 -> 0.28 | E38: ='01_MODELO'!E75 -> 0.28 | G38: =A38 -> Gastos explotación (% renta) | H38: {=_xlfn.SWITCH($H$23,$B$23,B38,$C$23,C38,$D$23,D38,$E$23,E38)} -> 0.28
A39: NOI anual (€) | B39: =B37*(1-B38) -> 189627.06 | C39: =C37*(1-C38) -> 222478.76 | D39: =D37*(1-D38) -> 325594.34 | E39: =E37*(1-E38) -> 475868.65 | G39: =A39 -> NOI anual (€) | H39: {=_xlfn.SWITCH($H$23,$B$23,B39,$C$23,C39,$D$23,D39,$E$23,E39)} -> 189627.06
A40: Yield mercado (%) | B40: ='01_MODELO'!B76 -> 0.06 | C40: ='01_MODELO'!C76 -> 0.06 | D40: ='01_MODELO'!D76 -> 0.06 | E40: ='01_MODELO'!E76 -> 0.06 | G40: =A40 -> Yield mercado (%) | H40: {=_xlfn.SWITCH($H$23,$B$23,B40,$C$23,C40,$D$23,D40,$E$23,E40)} -> 0.06
A41: Valor capitalizado (€) | B41: =B39/B40 -> 3160451 | C41: =C39/C40 -> 3707979.3 | D41: =D39/D40 -> 5426572.3 | E41: =E39/E40 -> 7931144.2 | G41: =A41 -> Valor capitalizado (€) | H41: {=_xlfn.SWITCH($H$23,$B$23,B41,$C$23,C41,$D$23,D41,$E$23,E41)} -> 3160451
...

Sheet 20_FINANCIACION
A1: VARIABLES DE FINANCIACIÓN
A2: Variable | B2: Base | C2: Unidad | E2: Base sin sensibilidad
A3: PARÁMETROS COMUNES (build-up de Tipo de interés y Ke)
A4: Euríbor 12m de referencia | B4: =E4+'02_ESCENARIOS'!G21 -> 0.0275 | C4: % | E4: 0.0275
A5: Diferencial bancario | B5: 0.0275 | C5: %
A6: Tasa libre de riesgo (Bono España 10Y) | B6: 0.03114 | C6: %
A7: Equity Risk Premium España | B7: 0.058 | C7: %
A8: Prima de tamaño (small developer) | B8: 0.02 | C8: %
A9: Prima específica del proyecto | B9: =2%-0.41% -> 0.0159 | C9: %
A10: PARÁMETROS USADOS EN 32_CASHFLOW (levered)
A11: Loan to Cost (LTC) | B11: 0.65 | C11: % | E11: ='00_ESTRATEGIA'!B14 -> 1570326
A12: Tipo de interés nominal | B12: =B4+B5 -> 0.055 | C12: %
A13: Mes formalización préstamo | B13: ='01_MODELO'!I35 -> 11 | C13: mes
A14: Mes inicio amortización por ventas | B14: ='01_MODELO'!I37 -> 35 | C14: mes
A15: % de cada venta a cancelación | B15: 0.85 | C15: %
A16: Tipo IS aplicable | B16: 0.25 | C16: %
A17: Coste de capital propio (Ke) | B17: =B6+B7+B8+B9 -> 0.12504 | C17: %
A18: PARÁMETROS USADOS EN 33_CASHFLOW (partner)
A19: % partner sobre ejecución | B19: 0.5 | C19: %
A20: Hurdle rate (preferred return) anual | B20: 0.08 | C20: %
A21: Split sobre exceso — Promotor | B21: 0.7 | C21: %
A22: Split sobre exceso — Partner | B22: 0.3 | C22: %
A23: Mes de entrada del partner | B23: ='01_MODELO'!I35 -> 11 | C23: mes
A24: Comisión de apertura (% sobre nominal aprobado) | B24: 0.0075 | C24: %
A25: Comisión de no disponibilidad (% anual sobre saldo no dispuesto) | B25: 0.005 | C25: %

Sheet 30_CASHFLOW
A1: CASHFLOW MENSUAL
A2: Tipología: | B2: ='00_ESTRATEGIA'!B3 -> Unifamiliar seg. | D2: Escenario: | E2: ='00_ESTRATEGIA'!B4 -> Base
A3: Concepto / Mes | B3: 0 | C3: 1 | D3: 2 | E3: 3 | F3: 4 | G3: 5 | H3: 6 | I3: 7 | J3: 8 | K3: 9 | L3: 10 | M3: 11 | N3: 12 | O3: 13 | P3: 14 | Q3: 15 | R3: 16 | S3: 17 | T3: 18 | U3: 19 | V3: 20 | W3: 21 | X3: 22 | Y3: 23 | Z3: 24 | AA3: 25 | AB3: 26 | AC3: 27 | AD3: 28 | AE3: 29 | AF3: 30 | AG3: 31 | AH3: 32 | AI3: 33 | AJ3: 34 | AK3: 35 | AL3: 36 | AM3: 37 | AN3: 38 | AO3: 39 | AP3: 40 | AQ3: 41 | AR3: 42 | AS3: 43 | AT3: 44 | AU3: 45 | AV3: 46 | AW3: 47 | AX3: 48 | AY3: 49 | AZ3: 50 | BA3: 51 | BB3: 52 | BC3: 53 | BD3: 54 | BE3: 55 | BF3: 56 | BG3: 57 | BH3: 58 | BI3: 59 | BJ3: 60 | BK3: 61 | BL3: 62 | BM3: 63 | BN3: 64 | BO3: 65 | BP3: 66 | BQ3: 67 | BR3: 68 | BS3: 69 | BT3: 70 | BU3: 71 | BV3: 72 | BW3: 73 | BX3: 74 | BY3: 75 | BZ3: 76 | CA3: 77 | CB3: 78 | CC3: 79 | CD3: 80 | CE3: 81 | CF3: 82 | CG3: 83 | CH3: 84 | CI3: 85 | CJ3: 86 | CK3: 87 | CL3: 88 | CM3: 89 | CN3: 90 | CO3: 91 | CP3: 92 | CQ3: 93 | CR3: 94 | CS3: 95 | CT3: 96 | CU3: 97 | CV3: 98 | CW3: 99 | CX3: 100 | CY3: 101 | CZ3: 102 | DA3: 103 | DB3: 104 | DC3: 105 | DD3: 106 | DE3: 107 | DF3: 108 | DG3: 109 | DH3: 110 | DI3: 111 | DJ3: 112 | DK3: 113 | DL3: 114 | DM3: 115 | DN3: 116 | DO3: 117 | DP3: 118 | DQ3: 119 | DR3: 120 | DS3: 121 | DT3: 122 | DU3: 123 | DV3: 124 | DW3: 125 | DX3: 126 | DY3: 127 | DZ3: 128 | EA3: 129 | EB3: 130 | EC3: 131 | ED3: 132 | EE3: 133 | EF3: 134 | EG3: 135 | EH3: 136 | EI3: 137 | EJ3: 138 | EK3: 139 | EL3: 140 | EM3: 141 | EN3: 142 | EO3: 143 | EP3: 144 | EQ3: 145 | ER3: 146 | ES3: 147 | ET3: 148 | EU3: 149 | EV3: 150 | EW3: 151 | EX3: 152 | EY3: 153 | EZ3: 154 | FA3: 155 | FB3: 156 | FC3: 157 | FD3: 158 | FE3: 159 | FF3: 160 | FG3: 161 | FH3: 162 | FI3: 163 | FJ3: 164 | FK3: 165 | FL3: 166 | FM3: 167 | FN3: 168 | FO3: 169 | FP3: 170 | FQ3: 171 | FR3: 172 | FS3: 173 | FT3: 174 | FU3: 175 | FV3: 176 | FW3: 177 | FX3: 178 | FY3: 179 | FZ3: 180
A4: Año | B4: Y0 | C4: Y0 | D4: Y0 | E4: Y0 | F4: Y0 | G4: Y0 | H4: Y0 | I4: Y0 | J4: Y0 | K4: Y0 | L4: Y0 | M4: Y0 | N4: Y1 | O4: Y1 | P4: Y1 | Q4: Y1 | R4: Y1 | S4: Y1 | T4: Y1 | U4: Y1 | V4: Y1 | W4: Y1 | X4: Y1 | Y4: Y1 | Z4: Y2 | AA4: Y2 | AB4: Y2 | AC4: Y2 | AD4: Y2 | AE4: Y2 | AF4: Y2 | AG4: Y2 | AH4: Y2 | AI4: Y2 | AJ4: Y2 | AK4: Y2 | AL4: Y3 | AM4: Y3 | AN4: Y3 | AO4: Y3 | AP4: Y3 | AQ4: Y3 | AR4: Y3 | AS4: Y3 | AT4: Y3 | AU4: Y3 | AV4: Y3 | AW4: Y3 | AX4: Y4 | AY4: Y4 | AZ4: Y4 | BA4: Y4 | BB4: Y4 | BC4: Y4 | BD4: Y4 | BE4: Y4 | BF4: Y4 | BG4: Y4 | BH4: Y4 | BI4: Y4 | BJ4: Y5 | BK4: Y5 | BL4: Y5 | BM4: Y5 | BN4: Y5 | BO4: Y5 | BP4: Y5 | BQ4: Y5 | BR4: Y5 | BS4: Y5 | BT4: Y5 | BU4: Y5 | BV4: Y6 | BW4: Y6 | BX4: Y6 | BY4: Y6 | BZ4: Y6 | CA4: Y6 | CB4: Y6 | CC4: Y6 | CD4: Y6 | CE4: Y6 | CF4: Y6 | CG4: Y6 | CH4: Y7 | CI4: Y7 | CJ4: Y7 | CK4: Y7 | CL4: Y7 | CM4: Y7 | CN4: Y7 | CO4: Y7 | CP4: Y7 | CQ4: Y7 | CR4: Y7 | CS4: Y7 | CT4: Y8 | CU4: Y8 | CV4: Y8 | CW4: Y8 | CX4: Y8 | CY4: Y8 | CZ4: Y8 | DA4: Y8 | DB4: Y8 | DC4: Y8 | DD4: Y8 | DE4: Y8 | DF4: Y9 | DG4: Y9 | DH4: Y9 | DI4: Y9 | DJ4: Y9 | DK4: Y9 | DL4: Y9 | DM4: Y9 | DN4: Y9 | DO4: Y9 | DP4: Y9 | DQ4: Y9 | DR4: Y10 | DS4: Y10 | DT4: Y10 | DU4: Y10 | DV4: Y10 | DW4: Y10 | DX4: Y10 | DY4: Y10 | DZ4: Y10 | EA4: Y10 | EB4: Y10 | EC4: Y10 | ED4: Y11 | EE4: Y11 | EF4: Y11 | EG4: Y11 | EH4: Y11 | EI4: Y11 | EJ4: Y11 | EK4: Y11 | EL4: Y11 | EM4: Y11 | EN4: Y11 | EO4: Y11 | EP4: Y12 | EQ4: Y12 | ER4: Y12 | ES4: Y12 | ET4: Y12 | EU4: Y12 | EV4: Y12 | EW4: Y12 | EX4: Y12 | EY4: Y12 | EZ4: Y12 | FA4: Y12 | FB4: Y13 | FC4: Y13 | FD4: Y13 | FE4: Y13 | FF4: Y13 | FG4: Y13 | FH4: Y13 | FI4: Y13 | FJ4: Y13 | FK4: Y13 | FL4: Y13 | FM4: Y13 | FN4: Y14 | FO4: Y14 | FP4: Y14 | FQ4: Y14 | FR4: Y14 | FS4: Y14 | FT4: Y14 | FU4: Y14 | FV4: Y14 | FW4: Y14 | FX4: Y14 | FY4: Y14 | FZ4: Y15
A5: CAPEX | B5: M0 | C5: M1 | D5: M2 | E5: M3 | F5: M4 | G5: M5 | H5: M6 | I5: M7 | J5: M8 | K5: M9 | L5: M10 | M5: M11 | N5: M12 | O5: M13 | P5: M14 | Q5: M15 | R5: M16
A6: Suelo | B6: =IF(B$3=0,-'10_CAPEX-INGRESOS-PAGOS'!$H$16,0) -> -1183546 | C6: =IF(C$3=0,-'10_CAPEX-INGRESOS-PAGOS'!$H$16,0) -> 0 | D6: =IF(D$3=0,-'10_CAPEX-INGRESOS-PAGOS'!$H$16,0) -> 0 | E6: =IF(E$3=0,-'10_CAPEX-INGRESOS-PAGOS'!$H$16,0) -> 0 | F6: =IF(F$3=0,-'10_CAPEX-INGRESOS-PAGOS'!$H$16,0) -> 0 | G6: =IF(G$3=0,-'10_CAPEX-INGRESOS-PAGOS'!$H$16,0) -> 0 | H6: =IF(H$3=0,-'10_CAPEX-INGRESOS-PAGOS'!$H$16,0) -> 0 | I6: =IF(I$3=0,-'10_CAPEX-INGRESOS-PAGOS'!$H$16,0) -> 0 | ... FZ6: =IF(FZ$3=0,-'10_CAPEX-INGRESOS-PAGOS'!$H$16,0) -> 0
A7: Construcción | B7: =-'10_CAPEX-INGRESOS-PAGOS'!$H$12*MAX(0,MIN(B$3+1,'01_MODELO'!$I$37)-MAX(B$3,'01_MODELO'!$I$35))/('01_MODELO'!$I$37-'01_MODELO'!$I$35) -> 0 | C7: =-'10_CAPEX-INGRESOS-PAGOS'!$H$12*MAX(0,MIN(C$3+1,'01_MODELO'!$I$37)-MAX(C$3,'01_MODELO'!$I$35))/('01_MODELO'!$I$37-'01_MODELO'!$I$35) -> 0 | D7: =-'10_CAPEX-INGRESOS-PAGOS'!$H$12*MAX(0,MIN(D$3+1,'01_MODELO'!$I$37)-MAX(D$3,'01_MODELO'!$I$35))/('01_MODELO'!$I$37-'01_MODELO'!$I$35) -> 0 | E7: =-'10_CAPEX-INGRESOS-PAGOS'!$H$12*MAX(0,MIN(E$3+1,'01_MODELO'!$I$37)-MAX(E$3,'01_MODELO'!$I$35))/('01_MODELO'!$I$37-'01_MODELO'!$I$35) -> 0 | F7: =-'10_CAPEX-INGRESOS-PAGOS'!$H$12*MAX(0,MIN(F$3+1,'01_MODELO'!$I$37)-MAX(F$3,'01_MODELO'!$I$35))/('01_MODELO'!$I$37-'01_MODELO'!$I$35) -> 0 | G7: =-'10_CAPEX-INGRESOS-PAGOS'!$H$12*MAX(0,MIN(G$3+1,'01_MODELO'!$I$37)-MAX(G$3,'01_MODELO'!$I$35))/('01_MODELO'!$I$37-'01_MODELO'!$I$35) -> 0 | H7: =-'10_CAPEX-INGRESOS-PAGOS'!$H$12*MAX(0,MIN(H$3+1,'01_MODELO'!$I$37)-MAX(H$3,'01_MODELO'!$I$35))/('01_MODELO'!$I$37-'01_MODELO'!$I$35) -> 0 | I7: =-'10_CAPEX-INGRESOS-PAGOS'!$H$12*MAX(0,MIN(I$3+1,'01_MODELO'!$I$37)-MAX(I$3,'01_MODELO'!$I$35))/('01_MODELO'!$I$37-'01_MODELO'!$I$35) -> 0 | ... FZ7: =-'10_CAPEX-INGRESOS-PAGOS'!$H$12*MAX(0,MIN(FZ$3+1,'01_MODELO'!$I$37)-MAX(FZ$3,'01_MODELO'!$I$35))/('01_MODELO'!$I$37-'01_MODELO'!$I$35) -> 0
A8: CAPEX Total | B8: =SUM(B6,B7) -> -1183546 | C8: =SUM(C6,C7) -> 0 | D8: =SUM(D6,D7) -> 0 | E8: =SUM(E6,E7) -> 0 | F8: =SUM(F6,F7) -> 0 | G8: =SUM(G6,G7) -> 0 | H8: =SUM(H6,H7) -> 0 | I8: =SUM(I6,I7) -> 0 | ... FZ8: =SUM(FZ6,FZ7) -> 0
A9: Ingresos Venta
A10: Unidades vendidas | B10: =IF(B$3<'01_MODELO'!$I$66,0,MAX(0,MIN('01_MODELO'!$I$64,'10_CAPEX-INGRESOS-PAGOS'!$H$3-IF(COLUMN()=COLUMN($B$10),0,SUM($B$10:INDEX($10:$10,COLUMN()-1)))))) -> 0 | C10: =IF(C$3<'01_MODELO'!$I$66,0,MAX(0,MIN('01_MODELO'!$I$64,'10_CAPEX-INGRESOS-PAGOS'!$H$3-IF(COLUMN()=COLUMN($B$10),0,SUM($B$10:INDEX($10:$10,COLUMN()-1)))))) -> 0 | D10: =IF(D$3<'01_MODELO'!$I$66,0,MAX(0,MIN('01_MODELO'!$I$64,'10_CAPEX-INGRESOS-PAGOS'!$H$3-IF(COLUMN()=COLUMN($B$10),0,SUM($B$10:INDEX($10:$10,COLUMN()-1)))))) -> 0 | E10: =IF(E$3<'01_MODELO'!$I$66,0,MAX(0,MIN('01_MODELO'!$I$64,'10_CAPEX-INGRESOS-PAGOS'!$H$3-IF(COLUMN()=COLUMN($B$10),0,SUM($B$10:INDEX($10:$10,COLUMN()-1)))))) -> 0 | F10: =IF(F$3<'01_MODELO'!$I$66,0,MAX(0,MIN('01_MODELO'!$I$64,'10_CAPEX-INGRESOS-PAGOS'!$H$3-IF(COLUMN()=COLUMN($B$10),0,SUM($B$10:INDEX($10:$10,COLUMN()-1)))))) -> 0 | G10: =IF(G$3<'01_MODELO'!$I$66,0,MAX(0,MIN('01_MODELO'!$I$64,'10_CAPEX-INGRESOS-PAGOS'!$H$3-IF(COLUMN()=COLUMN($B$10),0,SUM($B$10:INDEX($10:$10,COLUMN()-1)))))) -> 0 | H10: =IF(H$3<'01_MODELO'!$I$66,0,MAX(0,MIN('01_MODELO'!$I$64,'10_CAPEX-INGRESOS-PAGOS'!$H$3-IF(COLUMN()=COLUMN($B$10),0,SUM($B$10:INDEX($10:$10,COLUMN()-1)))))) -> 0 | I10: =IF(I$3<'01_MODELO'!$I$66,0,MAX(0,MIN('01_MODELO'!$I$64,'10_CAPEX-INGRESOS-PAGOS'!$H$3-IF(COLUMN()=COLUMN($B$10),0,SUM($B$10:INDEX($10:$10,COLUMN()-1)))))) -> 0 | ... FZ10: =IF(FZ$3<'01_MODELO'!$I$66,0,MAX(0,MIN('01_MODELO'!$I$64,'10_CAPEX-INGRESOS-PAGOS'!$H$3-IF(COLUMN()=COLUMN($B$10),0,SUM($B$10:INDEX($10:$10,COLUMN()-1)))))) -> 0
A11: % ventas | B11: =B10/'10_CAPEX-INGRESOS-PAGOS'!$H$3 -> 0 | C11: =C10/'10_CAPEX-INGRESOS-PAGOS'!$H$3 -> 0 | D11: =D10/'10_CAPEX-INGRESOS-PAGOS'!$H$3 -> 0 | E11: =E10/'10_CAPEX-INGRESOS-PAGOS'!$H$3 -> 0 | F11: =F10/'10_CAPEX-INGRESOS-PAGOS'!$H$3 -> 0 | G11: =G10/'10_CAPEX-INGRESOS-PAGOS'!$H$3 -> 0 | H11: =H10/'10_CAPEX-INGRESOS-PAGOS'!$H$3 -> 0 | I11: =I10/'10_CAPEX-INGRESOS-PAGOS'!$H$3 -> 0 | ... FZ11: =FZ10/'10_CAPEX-INGRESOS-PAGOS'!$H$3 -> 0
A12: Cobro reserva | B12: =B$10*'10_CAPEX-INGRESOS-PAGOS'!$H$27*'10_CAPEX-INGRESOS-PAGOS'!$H$45 -> 0 | C12: =C$10*'10_CAPEX-INGRESOS-PAGOS'!$H$27*'10_CAPEX-INGRESOS-PAGOS'!$H$45 -> 0 | D12: =D$10*'10_CAPEX-INGRESOS-PAGOS'!$H$27*'10_CAPEX-INGRESOS-PAGOS'!$H$45 -> 0 | E12: =E$10*'10_CAPEX-INGRESOS-PAGOS'!$H$27*'10_CAPEX-INGRESOS-PAGOS'!$H$45 -> 0 | F12: =F$10*'10_CAPEX-INGRESOS-PAGOS'!$H$27*'10_CAPEX-INGRESOS-PAGOS'!$H$45 -> 0 | G12: =G$10*'10_CAPEX-INGRESOS-PAGOS'!$H$27*'10_CAPEX-INGRESOS-PAGOS'!$H$45 -> 0 | H12: =H$10*'10_CAPEX-INGRESOS-PAGOS'!$H$27*'10_CAPEX-INGRESOS-PAGOS'!$H$45 -> 0 | I12: =I$10*'10_CAPEX-INGRESOS-PAGOS'!$H$27*'10_CAPEX-INGRESOS-PAGOS'!$H$45 -> 0 | ... FZ12: =FZ$10*'10_CAPEX-INGRESOS-PAGOS'!$H$27*'10_CAPEX-INGRESOS-PAGOS'!$H$45 -> 0
A13: Cobro contrato | B13: =IF(B$3>=2,INDEX($B$10:$FZ$10,1,MATCH(B$3-2,$B$3:$FZ$3,0))*'10_CAPEX-INGRESOS-PAGOS'!$H$27*'10_CAPEX-INGRESOS-PAGOS'!$H$46,0) -> 0 | C13: =IF(C$3>=2,INDEX($B$10:$FZ$10,1,MATCH(C$3-2,$B$3:$FZ$3,0))*'10_CAPEX-INGRESOS-PAGOS'!$H$27*'10_CAPEX-INGRESOS-PAGOS'!$H$46,0) -> 0 | D13: =IF(D$3>=2,INDEX($B$10:$FZ$10,1,MATCH(D$3-2,$B$3:$FZ$3,0))*'10_CAPEX-INGRESOS-PAGOS'!$H$27*'10_CAPEX-INGRESOS-PAGOS'!$H$46,0) -> 0 | E13: =IF(E$3>=2,INDEX($B$10:$FZ$10,1,MATCH(E$3-2,$B$3:$FZ$3,0))*'10_CAPEX-INGRESOS-PAGOS'!$H$27*'10_CAPEX-INGRESOS-PAGOS'!$H$46,0) -> 0 | F13: =IF(F$3>=2,INDEX($B$10:$FZ$10,1,MATCH(F$3-2,$B$3:$FZ$3,0))*'10_CAPEX-INGRESOS-PAGOS'!$H$27*'10_CAPEX-INGRESOS-PAGOS'!$H$46,0) -> 0 | G13: =IF(G$3>=2,INDEX($B$10:$FZ$10,1,MATCH(G$3-2,$B$3:$FZ$3,0))*'10_CAPEX-INGRESOS-PAGOS'!$H$27*'10_CAPEX-INGRESOS-PAGOS'!$H$46,0) -> 0 | H13: =IF(H$3>=2,INDEX($B$10:$FZ$10,1,MATCH(H$3-2,$B$3:$FZ$3,0))*'10_CAPEX-INGRESOS-PAGOS'!$H$27*'10_CAPEX-INGRESOS-PAGOS'!$H$46,0) -> 0 | I13: =IF(I$3>=2,INDEX($B$10:$FZ$10,1,MATCH(I$3-2,$B$3:$FZ$3,0))*'10_CAPEX-INGRESOS-PAGOS'!$H$27*'10_CAPEX-INGRESOS-PAGOS'!$H$46,0) -> 0 | ... FZ13: =IF(FZ$3>=2,INDEX($B$10:$FZ$10,1,MATCH(FZ$3-2,$B$3:$FZ$3,0))*'10_CAPEX-INGRESOS-PAGOS'!$H$27*'10_CAPEX-INGRESOS-PAGOS'!$H$46,0) -> 0
A14: Cobro aplazado lineal | B14: =IF(AND(B$3>=ROUNDUP('01_MODELO'!$I$66+2,0),B$3<=ROUNDUP('01_MODELO'!$I$37,0)),(SUMPRODUCT($B$10:$FZ$10,--($B$3:$FZ$3<ROUNDUP('01_MODELO'!$I$37,0)))*'10_CAPEX-INGRESOS-PAGOS'!$H$27)*'10_CAPEX-INGRESOS-PAGOS'!$H$47/(ROUNDUP('01_MODELO'!$I$37,0)-ROUNDUP('01_MODELO'!$I$66+2,0)+1),0) -> 0 | C14: =IF(AND(C$3>=ROUNDUP('01_MODELO'!$I$66+2,0),C$3<=ROUNDUP('01_MODELO'!$I$37,0)),(SUMPRODUCT($B$10:$FZ$10,--($B$3:$FZ$3<ROUNDUP('01_MODELO'!$I$37,0)))*'10_CAPEX-INGRESOS-PAGOS'!$H$27)*'10_CAPEX-INGRESOS-PAGOS'!$H$47/(ROUNDUP('01_MODELO'!$I$37,0)-ROUNDUP('01_MODELO'!$I$66+2,0)+1),0) -> 0 | D14: =IF(AND(D$3>=ROUNDUP('01_MODELO'!$I$66+2,0),D$3<=ROUNDUP('01_MODELO'!$I$37,0)),(SUMPRODUCT($B$10:$FZ$10,--($B$3:$FZ$3<ROUNDUP('01_MODELO'!$I$37,0)))*'10_CAPEX-INGRESOS-PAGOS'!$H$27)*'10_CAPEX-INGRESOS-PAGOS'!$H$47/(ROUNDUP('01_MODELO'!$I$37,0)-ROUNDUP('01_MODELO'!$I$66+2,0)+1),0) -> 0 | E14: =IF(AND(E$3>=ROUNDUP('01_MODELO'!$I$66+2,0),E$3<=ROUNDUP('01_MODELO'!$I$37,0)),(SUMPRODUCT($B$10:$FZ$10,--($B$3:$FZ$3<ROUNDUP('01_MODELO'!$I$37,0)))*'10_CAPEX-INGRESOS-PAGOS'!$H$27)*'10_CAPEX-INGRESOS-PAGOS'!$H$47/(ROUNDUP('01_MODELO'!$I$37,0)-ROUNDUP('01_MODELO'!$I$66+2,0)+1),0) -> 0 | F14: =IF(AND(F$3>=ROUNDUP('01_MODELO'!$I$66+2,0),F$3<=ROUNDUP('01_MODELO'!$I$37,0)),(SUMPRODUCT($B$10:$FZ$10,--($B$3:$FZ$3<ROUNDUP('01_MODELO'!$I$37,0)))*'10_CAPEX-INGRESOS-PAGOS'!$H$27)*'10_CAPEX-INGRESOS-PAGOS'!$H$47/(ROUNDUP('01_MODELO'!$I$37,0)-ROUNDUP('01_MODELO'!$I$66+2,0)+1),0) -> 0 | G14: =IF(AND(G$3>=ROUNDUP('01_MODELO'!$I$66+2,0),G$3<=ROUNDUP('01_MODELO'!$I$37,0)),(SUMPRODUCT($B$10:$FZ$10,--($B$3:$FZ$3<ROUNDUP('01_MODELO'!$I$37,0)))*'10_CAPEX-INGRESOS-PAGOS'!$H$27)*'10_CAPEX-INGRESOS-PAGOS'!$H$47/(ROUNDUP('01_MODELO'!$I$37,0)-ROUNDUP('01_MODELO'!$I$66+2,0)+1),0) -> 0 | H14: =IF(AND(H$3>=ROUNDUP('01_MODELO'!$I$66+2,0),H$3<=ROUNDUP('01_MODELO'!$I$37,0)),(SUMPRODUCT($B$10:$FZ$10,--($B$3:$FZ$3<ROUNDUP('01_MODELO'!$I$37,0)))*'10_CAPEX-INGRESOS-PAGOS'!$H$27)*'10_CAPEX-INGRESOS-PAGOS'!$H$47/(ROUNDUP('01_MODELO'!$I$37,0)-ROUNDUP('01_MODELO'!$I$66+2,0)+1),0) -> 0 | I14: =IF(AND(I$3>=ROUNDUP('01_MODELO'!$I$66+2,0),I$3<=ROUNDUP('01_MODELO'!$I$37,0)),(SUMPRODUCT($B$10:$FZ$10,--($B$3:$FZ$3<ROUNDUP('01_MODELO'!$I$37,0)))*'10_CAPEX-INGRESOS-PAGOS'!$H$27)*'10_CAPEX-INGRESOS-PAGOS'!$H$47/(ROUNDUP('01_MODELO'!$I$37,0)-ROUNDUP('01_MODELO'!$I$66+2,0)+1),0) -> 0 | ... FZ14: =IF(AND(FZ$3>=ROUNDUP('01_MODELO'!$I$66+2,0),FZ$3<=ROUNDUP('01_MODELO'!$I$37,0)),(SUMPRODUCT($B$10:$FZ$10,--($B$3:$FZ$3<ROUNDUP('01_MODELO'!$I$37,0)))*'10_CAPEX-INGRESOS-PAGOS'!$H$27)*'10_CAPEX-INGRESOS-PAGOS'!$H$47/(ROUNDUP('01_MODELO'!$I$37,0)-ROUNDUP('01_MODELO'!$I$66+2,0)+1),0) -> 0
A15: Escritura fin de obra | B15: =IF(B$3=ROUNDUP('01_MODELO'!$I$37,0),(SUMPRODUCT($B$10:$FZ$10,--($B$3:$FZ$3<ROUNDUP('01_MODELO'!$I$37,0)))*'10_CAPEX-INGRESOS-PAGOS'!$H$27)*'10_CAPEX-INGRESOS-PAGOS'!$H$48,0) -> 0 | C15: =IF(C$3=ROUNDUP('01_MODELO'!$I$37,0),(SUMPRODUCT($B$10:$FZ$10,--($B$3:$FZ$3<ROUNDUP('01_MODELO'!$I$37,0)))*'10_CAPEX-INGRESOS-PAGOS'!$H$27)*'10_CAPEX-INGRESOS-PAGOS'!$H$48,0) -> 0 | D15: =IF(D$3=ROUNDUP('01_MODELO'!$I$37,0),(SUMPRODUCT($B$10:$FZ$10,--($B$3:$FZ$3<ROUNDUP('01_MODELO'!$I$37,0)))*'10_CAPEX-INGRESOS-PAGOS'!$H$27)*'10_CAPEX-INGRESOS-PAGOS'!$H$48,0) -> 0 | E15: =IF(E$3=ROUNDUP('01_MODELO'!$I$37,0),(SUMPRODUCT($B$10:$FZ$10,--($B$3:$FZ$3<ROUNDUP('01_MODELO'!$I$37,0)))*'10_CAPEX-INGRESOS-PAGOS'!$H$27)*'10_CAPEX-INGRESOS-PAGOS'!$H$48,0) -> 0 | F15: =IF(F$3=ROUNDUP('01_MODELO'!$I$37,0),(SUMPRODUCT($B$10:$FZ$10,--($B$3:$FZ$3<ROUNDUP('01_MODELO'!$I$37,0)))*'10_CAPEX-INGRESOS-PAGOS'!$H$27)*'10_CAPEX-INGRESOS-PAGOS'!$H$48,0) -> 0 | G15: =IF(G$3=ROUNDUP('01_MODELO'!$I$37,0),(SUMPRODUCT($B$10:$FZ$10,--($B$3:$FZ$3<ROUNDUP('01_MODELO'!$I$37,0)))*'10_CAPEX-INGRESOS-PAGOS'!$H$27)*'10_CAPEX-INGRESOS-PAGOS'!$H$48,0) -> 0 | H15: =IF(H$3=ROUNDUP('01_MODELO'!$I$37,0),(SUMPRODUCT($B$10:$FZ$10,--($B$3:$FZ$3<ROUNDUP('01_MODELO'!$I$37,0)))*'10_CAPEX-INGRESOS-PAGOS'!$H$27)*'10_CAPEX-INGRESOS-PAGOS'!$H$48,0) -> 0 | I15: =IF(I$3=ROUNDUP('01_MODELO'!$I$37,0),(SUMPRODUCT($B$10:$FZ$10,--($B$3:$FZ$3<ROUNDUP('01_MODELO'!$I$37,0)))*'10_CAPEX-INGRESOS-PAGOS'!$H$27)*'10_CAPEX-INGRESOS-PAGOS'!$H$48,0) -> 0 | ... FZ15: =IF(FZ$3=ROUNDUP('01_MODELO'!$I$37,0),(SUMPRODUCT($B$10:$FZ$10,--($B$3:$FZ$3<ROUNDUP('01_MODELO'!$I$37,0)))*'10_CAPEX-INGRESOS-PAGOS'!$H$27)*'10_CAPEX-INGRESOS-PAGOS'!$H$48,0) -> 0
A16: Escritura post fin de obra | B16: =SUMPRODUCT($B$10:$FZ$10*'10_CAPEX-INGRESOS-PAGOS'!$H$27*'10_CAPEX-INGRESOS-PAGOS'!$H$50*--($B$3:$FZ$3>=ROUNDUP('01_MODELO'!$I$37,0))*--($B$3:$FZ$3+2=B$3)) -> 0 | C16: =SUMPRODUCT($B$10:$FZ$10*'10_CAPEX-INGRESOS-PAGOS'!$H$27*'10_CAPEX-INGRESOS-PAGOS'!$H$50*--($B$3:$FZ$3>=ROUNDUP('01_MODELO'!$I$37,0))*--($B$3:$FZ$3+2=C$3)) -> 0 | D16: =SUMPRODUCT($B$10:$FZ$10*'10_CAPEX-INGRESOS-PAGOS'!$H$27*'10_CAPEX-INGRESOS-PAGOS'!$H$50*--($B$3:$FZ$3>=ROUNDUP('01_MODELO'!$I$37,0))*--($B$3:$FZ$3+2=D$3)) -> 0 | E16: =SUMPRODUCT($B$10:$FZ$10*'10_CAPEX-INGRESOS-PAGOS'!$H$27*'10_CAPEX-INGRESOS-PAGOS'!$H$50*--($B$3:$FZ$3>=ROUNDUP('01_MODELO'!$I$37,0))*--($B$3:$FZ$3+2=E$3)) -> 0 | F16: =SUMPRODUCT($B$10:$FZ$10*'10_CAPEX-INGRESOS-PAGOS'!$H$27*'10_CAPEX-INGRESOS-PAGOS'!$H$50*--($B$3:$FZ$3>=ROUNDUP('01_MODELO'!$I$37,0))*--($B$3:$FZ$3+2=F$3)) -> 0 | G16: =SUMPRODUCT($B$10:$FZ$10*'10_CAPEX-INGRESOS-PAGOS'!$H$27*'10_CAPEX-INGRESOS-PAGOS'!$H$50*--($B$3:$FZ$3>=ROUNDUP('01_MODELO'!$I$37,0))*--($B$3:$FZ$3+2=G$3)) -> 0 | H16: =SUMPRODUCT($B$10:$FZ$10*'10_CAPEX-INGRESOS-PAGOS'!$H$27*'10_CAPEX-INGRESOS-PAGOS'!$H$50*--($B$3:$FZ$3>=ROUNDUP('01_MODELO'!$I$37,0))*--($B$3:$FZ$3+2=H$3)) -> 0 | I16: =SUMPRODUCT($B$10:$FZ$10*'10_CAPEX-INGRESOS-PAGOS'!$H$27*'10_CAPEX-INGRESOS-PAGOS'!$H$50*--($B$3:$FZ$3>=ROUNDUP('01_MODELO'!$I$37,0))*--($B$3:$FZ$3+2=I$3)) -> 0 | ... FZ16: =SUMPRODUCT($B$10:$FZ$10*'10_CAPEX-INGRESOS-PAGOS'!$H$27*'10_CAPEX-INGRESOS-PAGOS'!$H$50*--($B$3:$FZ$3>=ROUNDUP('01_MODELO'!$I$37,0))*--($B$3:$FZ$3+2=FZ$3)) -> 0
A17: Total cobro ventas (bruto) | B17: =SUM(B$12:B$16) -> 0 | C17: =SUM(C$12:C$16) -> 0 | D17: =SUM(D$12:D$16) -> 0 | E17: =SUM(E$12:E$16) -> 0 | F17: =SUM(F$12:F$16) -> 0 | G17: =SUM(G$12:G$16) -> 0 | H17: =SUM(H$12:H$16) -> 0 | I17: =SUM(I$12:I$16) -> 0 | ... FZ17: =SUM(FZ$12:FZ$16) -> 0
A18: Coste comercialización | B18: =B$10*'10_CAPEX-INGRESOS-PAGOS'!$H$27*'10_CAPEX-INGRESOS-PAGOS'!$H$29 -> 0 | C18: =C$10*'10_CAPEX-INGRESOS-PAGOS'!$H$27*'10_CAPEX-INGRESOS-PAGOS'!$H$29 -> 0 | D18: =D$10*'10_CAPEX-INGRESOS-PAGOS'!$H$27*'10_CAPEX-INGRESOS-PAGOS'!$H$29 -> 0 | E18: =E$10*'10_CAPEX-INGRESOS-PAGOS'!$H$27*'10_CAPEX-INGRESOS-PAGOS'!$H$29 -> 0 | F18: =F$10*'10_CAPEX-INGRESOS-PAGOS'!$H$27*'10_CAPEX-INGRESOS-PAGOS'!$H$29 -> 0 | G18: =G$10*'10_CAPEX-INGRESOS-PAGOS'!$H$27*'10_CAPEX-INGRESOS-PAGOS'!$H$29 -> 0 | H18: =H$10*'10_CAPEX-INGRESOS-PAGOS'!$H$27*'10_CAPEX-INGRESOS-PAGOS'!$H$29 -> 0 | I18: =I$10*'10_CAPEX-INGRESOS-PAGOS'!$H$27*'10_CAPEX-INGRESOS-PAGOS'!$H$29 -> 0 | ... FZ18: =FZ$10*'10_CAPEX-INGRESOS-PAGOS'!$H$27*'10_CAPEX-INGRESOS-PAGOS'!$H$29 -> 0
A19: Ingresos netos venta | B19: =B$17-B$18 -> 0 | C19: =C$17-C$18 -> 0 | D19: =D$17-D$18 -> 0 | E19: =E$17-E$18 -> 0 | F19: =F$17-F$18 -> 0 | G19: =G$17-G$18 -> 0 | H19: =H$17-H$18 -> 0 | I19: =I$17-I$18 -> 0 | ... FZ19: =FZ$17-FZ$18 -> 0
A20: Flujo neto venta + CAPEX | B20: =B$8+B$19 -> -1183546 | C20: =C$8+C$19 -> 0 | D20: =D$8+D$19 -> 0 | E20: =E$8+E$19 -> 0 | F20: =F$8+F$19 -> 0 | G20: =G$8+G$19 -> 0 | H20: =H$8+H$19 -> 0 | I20: =I$8+I$19 -> 0 | ... FZ20: =FZ$8+FZ$19 -> 0
A21: Alquiler
A22: Ingresos alquiler | B22: =IF(B$3>='01_MODELO'!$I$78,IF(B$3<='00_ESTRATEGIA'!$B$5*12,'10_CAPEX-INGRESOS-PAGOS'!$H$35/12*(1+B$3/12*'01_MODELO'!$I$77),0),0) -> 0 | C22: =IF(C$3>='01_MODELO'!$I$78,IF(C$3<='00_ESTRATEGIA'!$B$5*12,'10_CAPEX-INGRESOS-PAGOS'!$H$35/12*(1+C$3/12*'01_MODELO'!$I$77),0),0) -> 0 | D22: =IF(D$3>='01_MODELO'!$I$78,IF(D$3<='00_ESTRATEGIA'!$B$5*12,'10_CAPEX-INGRESOS-PAGOS'!$H$35/12*(1+D$3/12*'01_MODELO'!$I$77),0),0) -> 0 | E22: =IF(E$3>='01_MODELO'!$I$78,IF(E$3<='00_ESTRATEGIA'!$B$5*12,'10_CAPEX-INGRESOS-PAGOS'!$H$35/12*(1+E$3/12*'01_MODELO'!$I$77),0),0) -> 0 | F22: =IF(F$3>='01_MODELO'!$I$78,IF(F$3<='00_ESTRATEGIA'!$B$5*12,'10_CAPEX-INGRESOS-PAGOS'!$H$35/12*(1+F$3/12*'01_MODELO'!$I$77),0),0) -> 0 | G22: =IF(G$3>='01_MODELO'!$I$78,IF(G$3<='00_ESTRATEGIA'!$B$5*12,'10_CAPEX-INGRESOS-PAGOS'!$H$35/12*(1+G$3/12*'01_MODELO'!$I$77),0),0) -> 0 | H22: =IF(H$3>='01_MODELO'!$I$78,IF(H$3<='00_ESTRATEGIA'!$B$5*12,'10_CAPEX-INGRESOS-PAGOS'!$H$35/12*(1+H$3/12*'01_MODELO'!$I$77),0),0) -> 0 | I22: =IF(I$3>='01_MODELO'!$I$78,IF(I$3<='00_ESTRATEGIA'!$B$5*12,'10_CAPEX-INGRESOS-PAGOS'!$H$35/12*(1+I$3/12*'01_MODELO'!$I$77),0),0) -> 0 | ... FZ22: =IF(FZ$3>='01_MODELO'!$I$78,IF(FZ$3<='00_ESTRATEGIA'!$B$5*12,'10_CAPEX-INGRESOS-PAGOS'!$H$35/12*(1+FZ$3/12*'01_MODELO'!$I$77),0),0) -> 28909.442
A23: OPEX | B23: =B$22*'01_MODELO'!$I$75 -> 0 | C23: =C$22*'01_MODELO'!$I$75 -> 0 | D23: =D$22*'01_MODELO'!$I$75 -> 0 | E23: =E$22*'01_MODELO'!$I$75 -> 0 | F23: =F$22*'01_MODELO'!$I$75 -> 0 | G23: =G$22*'01_MODELO'!$I$75 -> 0 | H23: =H$22*'01_MODELO'!$I$75 -> 0 | I23: =I$22*'01_MODELO'!$I$75 -> 0 | ... FZ23: =FZ$22*'01_MODELO'!$I$75 -> 8094.6439
A24: NOI | B24: =B$22-B$23 -> 0 | C24: =C$22-C$23 -> 0 | D24: =D$22-D$23 -> 0 | E24: =E$22-E$23 -> 0 | F24: =F$22-F$23 -> 0 | G24: =G$22-G$23 -> 0 | H24: =H$22-H$23 -> 0 | I24: =I$22-I$23 -> 0 | ... FZ24: =FZ$22-FZ$23 -> 20814.799
A25: Valor terminal | B25: =IF(B$3='00_ESTRATEGIA'!$B$5*12,(B$24*12*(1+'01_MODELO'!$I$77))/('01_MODELO'!$I$76-'01_MODELO'!$I$77),0) -> 0 | C25: =IF(C$3='00_ESTRATEGIA'!$B$5*12,(C$24*12*(1+'01_MODELO'!$I$77))/('01_MODELO'!$I$76-'01_MODELO'!$I$77),0) -> 0 | D25: =IF(D$3='00_ESTRATEGIA'!$B$5*12,(D$24*12*(1+'01_MODELO'!$I$77))/('01_MODELO'!$I$76-'01_MODELO'!$I$77),0) -> 0 | E25: =IF(E$3='00_ESTRATEGIA'!$B$5*12,(E$24*12*(1+'01_MODELO'!$I$77))/('01_MODELO'!$I$76-'01_MODELO'!$I$77),0) -> 0 | F25: =IF(F$3='00_ESTRATEGIA'!$B$5*12,(F$24*12*(1+'01_MODELO'!$I$77))/('01_MODELO'!$I$76-'01_MODELO'!$I$77),0) -> 0 | G25: =IF(G$3='00_ESTRATEGIA'!$B$5*12,(G$24*12*(1+'01_MODELO'!$I$77))/('01_MODELO'!$I$76-'01_MODELO'!$I$77),0) -> 0 | H25: =IF(H$3='00_ESTRATEGIA'!$B$5*12,(H$24*12*(1+'01_MODELO'!$I$77))/('01_MODELO'!$I$76-'01_MODELO'!$I$77),0) -> 0 | I25: =IF(I$3='00_ESTRATEGIA'!$B$5*12,(I$24*12*(1+'01_MODELO'!$I$77))/('01_MODELO'!$I$76-'01_MODELO'!$I$77),0) -> 0 | ... FZ25: =IF(FZ$3='00_ESTRATEGIA'!$B$5*12,(FZ$24*12*(1+'01_MODELO'!$I$77))/('01_MODELO'!$I$76-'01_MODELO'!$I$77),0) -> 5633872.1
A26: Flujo neto alquiler + CAPEX | B26: =B$8+B$24+B$25 -> -1183546 | C26: =C$8+C$24+C$25 -> 0 | D26: =D$8+D$24+D$25 -> 0 | E26: =E$8+E$24+E$25 -> 0 | F26: =F$8+F$24+F$25 -> 0 | G26: =G$8+G$24+G$25 -> 0 | H26: =H$8+H$24+H$25 -> 0 | I26: =I$8+I$24+I$25 -> 0 | ... FZ26: =FZ$8+FZ$24+FZ$25 -> 5654686.9
A27: Financiación
A28: Equity aportado | B28: =MAX(0,-(B20+B29+B37+B38)) -> 1183546 | C28: =MAX(0,-(C20+C29+C37+C38)) -> 0 | D28: =MAX(0,-(D20+D29+D37+D38)) -> 0 | E28: =MAX(0,-(E20+E29+E37+E38)) -> 0 | F28: =MAX(0,-(F20+F29+F37+F38)) -> 0 | G28: =MAX(0,-(G20+G29+G37+G38)) -> 0 | H28: =MAX(0,-(H20+H29+H37+H38)) -> 0 | I28: =MAX(0,-(I20+I29+I37+I38)) -> 0 | ... FZ28: =MAX(0,-(FZ20+FZ29+FZ37+FZ38)) -> 0
A29: Deuda dispuesta | B29: =IF(AND(B$3>='20_FINANCIACION'!$B$13,B$3<'20_FINANCIACION'!$B$14),MAX(0,MIN(-'30_CASHFLOW'!B7,'20_FINANCIACION'!$B$11*ABS(SUM('30_CASHFLOW'!$B$7:$FZ$7)) - 0)),0) -> 0 | C29: =IF(AND(C$3>='20_FINANCIACION'!$B$13,C$3<'20_FINANCIACION'!$B$14),MAX(0,MIN(-'30_CASHFLOW'!C7,'20_FINANCIACION'!$B$11*ABS(SUM('30_CASHFLOW'!$B$7:$FZ$7)) - SUM($B$29:B29))),0) -> 0 | D29: =IF(AND(D$3>='20_FINANCIACION'!$B$13,D$3<'20_FINANCIACION'!$B$14),MAX(0,MIN(-'30_CASHFLOW'!D7,'20_FINANCIACION'!$B$11*ABS(SUM('30_CASHFLOW'!$B$7:$FZ$7)) - SUM($B$29:C29))),0) -> 0 | E29: =IF(AND(E$3>='20_FINANCIACION'!$B$13,E$3<'20_FINANCIACION'!$B$14),MAX(0,MIN(-'30_CASHFLOW'!E7,'20_FINANCIACION'!$B$11*ABS(SUM('30_CASHFLOW'!$B$7:$FZ$7)) - SUM($B$29:D29))),0) -> 0 | F29: =IF(AND(F$3>='20_FINANCIACION'!$B$13,F$3<'20_FINANCIACION'!$B$14),MAX(0,MIN(-'30_CASHFLOW'!F7,'20_FINANCIACION'!$B$11*ABS(SUM('30_CASHFLOW'!$B$7:$FZ$7)) - SUM($B$29:E29))),0) -> 0 | G29: =IF(AND(G$3>='20_FINANCIACION'!$B$13,G$3<'20_FINANCIACION'!$B$14),MAX(0,MIN(-'30_CASHFLOW'!G7,'20_FINANCIACION'!$B$11*ABS(SUM('30_CASHFLOW'!$B$7:$FZ$7)) - SUM($B$29:F29))),0) -> 0 | H29: =IF(AND(H$3>='20_FINANCIACION'!$B$13,H$3<'20_FINANCIACION'!$B$14),MAX(0,MIN(-'30_CASHFLOW'!H7,'20_FINANCIACION'!$B$11*ABS(SUM('30_CASHFLOW'!$B$7:$FZ$7)) - SUM($B$29:G29))),0) -> 0 | I29: =IF(AND(I$3>='20_FINANCIACION'!$B$13,I$3<'20_FINANCIACION'!$B$14),MAX(0,MIN(-'30_CASHFLOW'!I7,'20_FINANCIACION'!$B$11*ABS(SUM('30_CASHFLOW'!$B$7:$FZ$7)) - SUM($B$29:H29))),0) -> 0 | J29: =IF(AND(J$3>='20_FINANCIACION'!$B$13,J$3<'20_FINANCIACION'!$B$14),MAX(0,MIN(-'30_CASHFLOW'!J7,'20_FINANCIACION'!$B$11*ABS(SUM('30_CASHFLOW'!$B$7:$FZ$7)) - SUM($B$29:I29))),0) -> 0 | ... FZ29: =IF(AND(FZ$3>='20_FINANCIACION'!$B$13,FZ$3<'20_FINANCIACION'!$B$14),MAX(0,MIN(-'30_CASHFLOW'!FZ7,'20_FINANCIACION'!$B$11*ABS(SUM('30_CASHFLOW'!$B$7:$FZ$7)) - SUM($B$29:FY29))),0) -> 0
A30: Total entradas financiación | B30: =B28+B29 -> 1183546 | C30: =C28+C29 -> 0 | D30: =D28+D29 -> 0 | E30: =E28+E29 -> 0 | F30: =F28+F29 -> 0 | G30: =G28+G29 -> 0 | H30: =H28+H29 -> 0 | I30: =I28+I29 -> 0 | ... FZ30: =FZ28+FZ29 -> 0
A31: Servicio de la deuda
A32: Intereses devengados | B32: =(B29/2)*'20_FINANCIACION'!$B$12/12 -> 0 | C32: =(B40+C29/2)*'20_FINANCIACION'!$B$12/12 -> 0 | D32: =(C40+D29/2)*'20_FINANCIACION'!$B$12/12 -> 0 | E32: =(D40+E29/2)*'20_FINANCIACION'!$B$12/12 -> 0 | F32: =(E40+F29/2)*'20_FINANCIACION'!$B$12/12 -> 0 | G32: =(F40+G29/2)*'20_FINANCIACION'!$B$12/12 -> 0 | H32: =(G40+H29/2)*'20_FINANCIACION'!$B$12/12 -> 0 | I32: =(H40+I29/2)*'20_FINANCIACION'!$B$12/12 -> 0 | J32: =(I40+J29/2)*'20_FINANCIACION'!$B$12/12 -> 0 | ... FZ32: =(FY40+FZ29/2)*'20_FINANCIACION'!$B$12/12 -> 0
A33: Intereses capitalizados (no cash) | B33: =IF(B$3<'20_FINANCIACION'!$B$14,B32,0) -> 0 | C33: =IF(C$3<'20_FINANCIACION'!$B$14,C32,0) -> 0 | D33: =IF(D$3<'20_FINANCIACION'!$B$14,D32,0) -> 0 | E33: =IF(E$3<'20_FINANCIACION'!$B$14,E32,0) -> 0 | F33: =IF(F$3<'20_FINANCIACION'!$B$14,F32,0) -> 0 | G33: =IF(G$3<'20_FINANCIACION'!$B$14,G32,0) -> 0 | H33: =IF(H$3<'20_FINANCIACION'!$B$14,H32,0) -> 0 | I33: =IF(I$3<'20_FINANCIACION'!$B$14,I32,0) -> 0 | ... FZ33: =IF(FZ$3<'20_FINANCIACION'!$B$14,FZ32,0) -> 0
A34: Intereses pagados (cash) | B34: =B32-B33 -> 0 | C34: =C32-C33 -> 0 | D34: =D32-D33 -> 0 | E34: =E32-E33 -> 0 | F34: =F32-F33 -> 0 | G34: =G32-G33 -> 0 | H34: =H32-H33 -> 0 | I34: =I32-I33 -> 0 | ... FZ34: =FZ32-FZ33 -> 0
A35: Amortización por ventas | B35: =IF(B$3>='20_FINANCIACION'!$B$14,MIN('20_FINANCIACION'!$B$15*MAX(0,'30_CASHFLOW'!B19),0+B29+B33),0) -> 0 | C35: =IF(C$3>='20_FINANCIACION'!$B$14,MIN('20_FINANCIACION'!$B$15*MAX(0,'30_CASHFLOW'!C19),B40+C29+C33),0) -> 0 | D35: =IF(D$3>='20_FINANCIACION'!$B$14,MIN('20_FINANCIACION'!$B$15*MAX(0,'30_CASHFLOW'!D19),C40+D29+D33),0) -> 0 | E35: =IF(E$3>='20_FINANCIACION'!$B$14,MIN('20_FINANCIACION'!$B$15*MAX(0,'30_CASHFLOW'!E19),D40+E29+E33),0) -> 0 | F35: =IF(F$3>='20_FINANCIACION'!$B$14,MIN('20_FINANCIACION'!$B$15*MAX(0,'30_CASHFLOW'!F19),E40+F29+F33),0) -> 0 | G35: =IF(G$3>='20_FINANCIACION'!$B$14,MIN('20_FINANCIACION'!$B$15*MAX(0,'30_CASHFLOW'!G19),F40+G29+G33),0) -> 0 | H35: =IF(H$3>='20_FINANCIACION'!$B$14,MIN('20_FINANCIACION'!$B$15*MAX(0,'30_CASHFLOW'!H19),G40+H29+H33),0) -> 0 | I35: =IF(I$3>='20_FINANCIACION'!$B$14,MIN('20_FINANCIACION'!$B$15*MAX(0,'30_CASHFLOW'!I19),H40+I29+I33),0) -> 0 | J35: =IF(J$3>='20_FINANCIACION'!$B$14,MIN('20_FINANCIACION'!$B$15*MAX(0,'30_CASHFLOW'!J19),I40+J29+J33),0) -> 0 | ... FZ35: =IF(FZ$3>='20_FINANCIACION'!$B$14,MIN('20_FINANCIACION'!$B$15*MAX(0,'30_CASHFLOW'!FZ19),FY40+FZ29+FZ33),0) -> 0
A36: Comisiones (apertura + no disponibilidad) | B36: =-IF(B$3='20_FINANCIACION'!$B$13,'20_FINANCIACION'!$B$24*'20_FINANCIACION'!$B$11*ABS(SUM('30_CASHFLOW'!$B$7:$FZ$7)),0)-IF(AND(B$3>='20_FINANCIACION'!$B$13,B$3<'20_FINANCIACION'!$B$14),'20_FINANCIACION'!$B$25/12*MAX(0,'20_FINANCIACION'!$B$11*ABS(SUM('30_CASHFLOW'!$B$7:$FZ$7))-0),0) -> 0 | C36: =-IF(C$3='20_FINANCIACION'!$B$13,'20_FINANCIACION'!$B$24*'20_FINANCIACION'!$B$11*ABS(SUM('30_CASHFLOW'!$B$7:$FZ$7)),0)-IF(AND(C$3>='20_FINANCIACION'!$B$13,C$3<'20_FINANCIACION'!$B$14),'20_FINANCIACION'!$B$25/12*MAX(0,'20_FINANCIACION'!$B$11*ABS(SUM('30_CASHFLOW'!$B$7:$FZ$7))-SUM($B$29:B29)),0) -> 0 | D36: =-IF(D$3='20_FINANCIACION'!$B$13,'20_FINANCIACION'!$B$24*'20_FINANCIACION'!$B$11*ABS(SUM('30_CASHFLOW'!$B$7:$FZ$7)),0)-IF(AND(D$3>='20_FINANCIACION'!$B$13,D$3<'20_FINANCIACION'!$B$14),'20_FINANCIACION'!$B$25/12*MAX(0,'20_FINANCIACION'!$B$11*ABS(SUM('30_CASHFLOW'!$B$7:$FZ$7))-SUM($B$29:C29)),0) -> 0 | E36: =-IF(E$3='20_FINANCIACION'!$B$13,'20_FINANCIACION'!$B$24*'20_FINANCIACION'!$B$11*ABS(SUM('30_CASHFLOW'!$B$7:$FZ$7)),0)-IF(AND(E$3>='20_FINANCIACION'!$B$13,E$3<'20_FINANCIACION'!$B$14),'20_FINANCIACION'!$B$25/12*MAX(0,'20_FINANCIACION'!$B$11*ABS(SUM('30_CASHFLOW'!$B$7:$FZ$7))-SUM($B$29:D29)),0) -> 0 | F36: =-IF(F$3='20_FINANCIACION'!$B$13,'20_FINANCIACION'!$B$24*'20_FINANCIACION'!$B$11*ABS(SUM('30_CASHFLOW'!$B$7:$FZ$7)),0)-IF(AND(F$3>='20_FINANCIACION'!$B$13,F$3<'20_FINANCIACION'!$B$14),'20_FINANCIACION'!$B$25/12*MAX(0,'20_FINANCIACION'!$B$11*ABS(SUM('30_CASHFLOW'!$B$7:$FZ$7))-SUM($B$29:E29)),0) -> 0 | G36: =-IF(G$3='20_FINANCIACION'!$B$13,'20_FINANCIACION'!$B$24*'20_FINANCIACION'!$B$11*ABS(SUM('30_CASHFLOW'!$B$7:$FZ$7)),0)-IF(AND(G$3>='20_FINANCIACION'!$B$13,G$3<'20_FINANCIACION'!$B$14),'20_FINANCIACION'!$B$25/12*MAX(0,'20_FINANCIACION'!$B$11*ABS(SUM('30_CASHFLOW'!$B$7:$FZ$7))-SUM($B$29:F29)),0) -> 0 | H36: =-IF(H$3='20_FINANCIACION'!$B$13,'20_FINANCIACION'!$B$24*'20_FINANCIACION'!$B$11*ABS(SUM('30_CASHFLOW'!$B$7:$FZ$7)),0)-IF(AND(H$3>='20_FINANCIACION'!$B$13,H$3<'20_FINANCIACION'!$B$14),'20_FINANCIACION'!$B$25/12*MAX(0,'20_FINANCIACION'!$B$11*ABS(SUM('30_CASHFLOW'!$B$7:$FZ$7))-SUM($B$29:G29)),0) -> 0 | I36: =-IF(I$3='20_FINANCIACION'!$B$13,'20_FINANCIACION'!$B$24*'20_FINANCIACION'!$B$11*ABS(SUM('30_CASHFLOW'!$B$7:$FZ$7)),0)-IF(AND(I$3>='20_FINANCIACION'!$B$13,I$3<'20_FINANCIACION'!$B$14),'20_FINANCIACION'!$B$25/12*MAX(0,'20_FINANCIACION'!$B$11*ABS(SUM('30_CASHFLOW'!$B$7:$FZ$7))-SUM($B$29:H29)),0) -> 0 | J36: =-IF(J$3='20_FINANCIACION'!$B$13,'20_FINANCIACION'!$B$24*'20_FINANCIACION'!$B$11*ABS(SUM('30_CASHFLOW'!$B$7:$FZ$7)),0)-IF(AND(J$3>='20_FINANCIACION'!$B$13,J$3<'20_FINANCIACION'!$B$14),'20_FINANCIACION'!$B$25/12*MAX(0,'20_FINANCIACION'!$B$11*ABS(SUM('30_CASHFLOW'!$B$7:$FZ$7))-SUM($B$29:I29)),0) -> 0 | ... FZ36: =-IF(FZ$3='20_FINANCIACION'!$B$13,'20_FINANCIACION'!$B$24*'20_FINANCIACION'!$B$11*ABS(SUM('30_CASHFLOW'!$B$7:$FZ$7)),0)-IF(AND(FZ$3>='20_FINANCIACION'!$B$13,FZ$3<'20_FINANCIACION'!$B$14),'20_FINANCIACION'!$B$25/12*MAX(0,'20_FINANCIACION'!$B$11*ABS(SUM('30_CASHFLOW'!$B$7:$FZ$7))-SUM($B$29:FY29)),0) -> 0
A37: Servicio total de la deuda (cash) | B37: =-B34-B35+B36 -> 0 | C37: =-C34-C35+C36 -> 0 | D37: =-D34-D35+D36 -> 0 | E37: =-E34-E35+E36 -> 0 | F37: =-F34-F35+F36 -> 0 | G37: =-G34-G35+G36 -> 0 | H37: =-H34-H35+H36 -> 0 | I37: =-I34-I35+I36 -> 0 | ... FZ37: =-FZ34-FZ35+FZ36 -> 0
A38: IS pagado (cash) | B38: =-IF(B$3=ROUNDUP('01_MODELO'!$I$37,0), MAX(0, (SUM('30_CASHFLOW'!$19:$19) + SUM('30_CASHFLOW'!$8:$8) - SUM($32:$32))) * '20_FINANCIACION'!$B$16, 0) -> 0 | C38: =-IF(C$3=ROUNDUP('01_MODELO'!$I$37,0), MAX(0, (SUM('30_CASHFLOW'!$19:$19) + SUM('30_CASHFLOW'!$8:$8) - SUM($32:$32))) * '20_FINANCIACION'!$B$16, 0) -> 0 | D38: =-IF(D$3=ROUNDUP('01_MODELO'!$I$37,0), MAX(0, (SUM('30_CASHFLOW'!$19:$19) + SUM('30_CASHFLOW'!$8:$8) - SUM($32:$32))) * '20_FINANCIACION'!$B$16, 0) -> 0 | E38: =-IF(E$3=ROUNDUP('01_MODELO'!$I$37,0), MAX(0, (SUM('30_CASHFLOW'!$19:$19) + SUM('30_CASHFLOW'!$8:$8) - SUM($32:$32))) * '20_FINANCIACION'!$B$16, 0) -> 0 | F38: =-IF(F$3=ROUNDUP('01_MODELO'!$I$37,0), MAX(0, (SUM('30_CASHFLOW'!$19:$19) + SUM('30_CASHFLOW'!$8:$8) - SUM($32:$32))) * '20_FINANCIACION'!$B$16, 0) -> 0 | G38: =-IF(G$3=ROUNDUP('01_MODELO'!$I$37,0), MAX(0, (SUM('30_CASHFLOW'!$19:$19) + SUM('30_CASHFLOW'!$8:$8) - SUM($32:$32))) * '20_FINANCIACION'!$B$16, 0) -> 0 | H38: =-IF(H$3=ROUNDUP('01_MODELO'!$I$37,0), MAX(0, (SUM('30_CASHFLOW'!$19:$19) + SUM('30_CASHFLOW'!$8:$8) - SUM($32:$32))) * '20_FINANCIACION'!$B$16, 0) -> 0 | I38: =-IF(I$3=ROUNDUP('01_MODELO'!$I$37,0), MAX(0, (SUM('30_CASHFLOW'!$19:$19) + SUM('30_CASHFLOW'!$8:$8) - SUM($32:$32))) * '20_FINANCIACION'!$B$16, 0) -> 0 | ... FZ38: =-IF(FZ$3=ROUNDUP('01_MODELO'!$I$37,0), MAX(0, (SUM('30_CASHFLOW'!$19:$19) + SUM('30_CASHFLOW'!$8:$8) - SUM($32:$32))) * '20_FINANCIACION'!$B$16, 0) -> 0
A39: Cashflow del accionista | B39: =B20+B29+B37+B38 -> -1183546 | C39: =C20+C29+C37+C38 -> 0 | D39: =D20+D29+D37+D38 -> 0 | E39: =E20+E29+E37+E38 -> 0 | F39: =F20+F29+F37+F38 -> 0 | G39: =G20+G29+G37+G38 -> 0 | H39: =H20+H29+H37+H38 -> 0 | I39: =I20+I29+I37+I38 -> 0 | ... FZ39: =FZ20+FZ29+FZ37+FZ38 -> 0
A40: Saldo vivo del préstamo (memoria) | B40: =B29+B33-B35 -> 0 | C40: =B40+C29+C33-C35 -> 0 | D40: =C40+D29+D33-D35 -> 0 | E40: =D40+E29+E33-E35 -> 0 | F40: =E40+F29+F33-F35 -> 0 | G40: =F40+G29+G33-G35 -> 0 | H40: =G40+H29+H33-H35 -> 0 | I40: =H40+I29+I33-I35 -> 0 | J40: =I40+J29+J33-J35 -> 0 | ... FZ40: =FY40+FZ29+FZ33-FZ35 -> 0
...

Sheet 31_P&L
A1: CUENTA DE RESULTADOS MENSUAL
A2: Tipología: | B2: ='00_ESTRATEGIA'!B3 -> Unifamiliar seg. | D2: Escenario: | E2: ='00_ESTRATEGIA'!B4 -> Base
A3: Mes | B3: 0 | C3: 1 | D3: 2 | E3: 3 | F3: 4 | G3: 5 | H3: 6 | I3: 7 | J3: 8 | K3: 9 | L3: 10 | M3: 11 | N3: 12 | O3: 13 | P3: 14 | Q3: 15 | R3: 16 | S3: 17 | T3: 18 | U3: 19 | V3: 20 | W3: 21 | X3: 22 | Y3: 23 | Z3: 24 | AA3: 25 | AB3: 26 | AC3: 27 | AD3: 28 | AE3: 29 | AF3: 30 | AG3: 31 | AH3: 32 | AI3: 33 | AJ3: 34 | AK3: 35 | AL3: 36 | AM3: 37 | AN3: 38 | AO3: 39 | AP3: 40 | AQ3: 41 | AR3: 42 | AS3: 43 | AT3: 44 | AU3: 45 | AV3: 46 | AW3: 47 | AX3: 48 | AY3: 49 | AZ3: 50 | BA3: 51 | BB3: 52 | BC3: 53 | BD3: 54 | BE3: 55 | BF3: 56 | BG3: 57 | BH3: 58 | BI3: 59
A4: Año | B4: Y0 | C4: Y0 | D4: Y0 | E4: Y0 | F4: Y0 | G4: Y0 | H4: Y0 | I4: Y0 | J4: Y0 | K4: Y0 | L4: Y0 | M4: Y0 | N4: Y1 | O4: Y1 | P4: Y1 | Q4: Y1 | R4: Y1 | S4: Y1 | T4: Y1 | U4: Y1 | V4: Y1 | W4: Y1 | X4: Y1 | Y4: Y1 | Z4: Y2 | AA4: Y2 | AB4: Y2 | AC4: Y2 | AD4: Y2 | AE4: Y2 | AF4: Y2 | AG4: Y2 | AH4: Y2 | AI4: Y2 | AJ4: Y2 | AK4: Y2 | AL4: Y3 | AM4: Y3 | AN4: Y3 | AO4: Y3 | AP4: Y3 | AQ4: Y3 | AR4: Y3 | AS4: Y3 | AT4: Y3 | AU4: Y3 | AV4: Y3 | AW4: Y3 | AX4: Y4 | AY4: Y4 | AZ4: Y4 | BA4: Y4 | BB4: Y4 | BC4: Y4 | BD4: Y4 | BE4: Y4 | BF4: Y4 | BG4: Y4 | BH4: Y4 | BI4: Y4
A5: INGRESOS
A6: Ingresos reconocidos por escritura / entrega | B6: =IFERROR('30_CASHFLOW'!B15/'10_CAPEX-INGRESOS-PAGOS'!$H$48,0)+IFERROR('30_CASHFLOW'!B16/'10_CAPEX-INGRESOS-PAGOS'!$H$50,0) -> 0 | C6: =IFERROR('30_CASHFLOW'!C15/'10_CAPEX-INGRESOS-PAGOS'!$H$48,0)+IFERROR('30_CASHFLOW'!C16/'10_CAPEX-INGRESOS-PAGOS'!$H$50,0) -> 0 | D6: =IFERROR('30_CASHFLOW'!D15/'10_CAPEX-INGRESOS-PAGOS'!$H$48,0)+IFERROR('30_CASHFLOW'!D16/'10_CAPEX-INGRESOS-PAGOS'!$H$50,0) -> 0 | E6: =IFERROR('30_CASHFLOW'!E15/'10_CAPEX-INGRESOS-PAGOS'!$H$48,0)+IFERROR('30_CASHFLOW'!E16/'10_CAPEX-INGRESOS-PAGOS'!$H$50,0) -> 0 | F6: =IFERROR('30_CASHFLOW'!F15/'10_CAPEX-INGRESOS-PAGOS'!$H$48,0)+IFERROR('30_CASHFLOW'!F16/'10_CAPEX-INGRESOS-PAGOS'!$H$50,0) -> 0 | G6: =IFERROR('30_CASHFLOW'!G15/'10_CAPEX-INGRESOS-PAGOS'!$H$48,0)+IFERROR('30_CASHFLOW'!G16/'10_CAPEX-INGRESOS-PAGOS'!$H$50,0) -> 0 | H6: =IFERROR('30_CASHFLOW'!H15/'10_CAPEX-INGRESOS-PAGOS'!$H$48,0)+IFERROR('30_CASHFLOW'!H16/'10_CAPEX-INGRESOS-PAGOS'!$H$50,0) -> 0 | I6: =IFERROR('30_CASHFLOW'!I15/'10_CAPEX-INGRESOS-PAGOS'!$H$48,0)+IFERROR('30_CASHFLOW'!I16/'10_CAPEX-INGRESOS-PAGOS'!$H$50,0) -> 0 | ... BI6: =IFERROR('30_CASHFLOW'!BI15/'10_CAPEX-INGRESOS-PAGOS'!$H$48,0)+IFERROR('30_CASHFLOW'!BI16/'10_CAPEX-INGRESOS-PAGOS'!$H$50,0) -> 0
A7: TOTAL INGRESOS | B7: =SUM(B6:B6) -> 0 | C7: =SUM(C6:C6) -> 0 | D7: =SUM(D6:D6) -> 0 | E7: =SUM(E6:E6) -> 0 | F7: =SUM(F6:F6) -> 0 | G7: =SUM(G6:G6) -> 0 | H7: =SUM(H6:H6) -> 0 | I7: =SUM(I6:I6) -> 0 | ... BI7: =SUM(BI6:BI6) -> 0
A9: COSTES OPERATIVOS
